{"cells":[{"cell_type":"markdown","metadata":{"id":"7h4JF6ZSmcU_"},"source":["Up to now, the environment is set up."]},{"cell_type":"code","execution_count":null,"metadata":{"id":"PO2Bw-pDz5f6"},"outputs":[],"source":["#! python experiments/train_KL_mode.py --exp-name exp14 --scenario simple_adversary --train-mode --train-adv --adv-policy ddpg --train-good --good-policy maddpg"]},{"cell_type":"code","execution_count":null,"metadata":{"id":"hXP9KLlVDXfl"},"outputs":[],"source":["#! python experiments/train_KL_mode.py --exp-name exp15 --scenario simple_adversary --train-mode --train-adv --adv-policy ddpg --train-good --good-policy kl"]},{"cell_type":"code","execution_count":null,"metadata":{"id":"mBjoT6KOHZkj"},"outputs":[],"source":["#! python experiments/train_KL_mode.py --exp-name exp13 --scenario simple_adversary --train-mode --train-adv --adv-policy kl --train-good --good-policy maddpg\n","python train_KL_mode.py --exp-name exp01 --scenario simple_tag --train-mode --train-adv --adv-policy kl --train-good --good-policy kl"]},{"cell_type":"code","execution_count":null,"metadata":{"id":"6lh4jDL2kqmU"},"outputs":[],"source":["#! python experiments/train_KL_mode.py --exp-name exp16 --scenario simple_crypto --train-mode --train-adv --adv-policy ddpg --train-good --good-policy maddpg"]},{"cell_type":"code","execution_count":null,"metadata":{"id":"Hz2B7bLxkqy_"},"outputs":[],"source":["#! python experiments/train_KL_mode.py --exp-name exp17 --scenario simple_crypto --train-mode --train-adv --adv-policy ddpg --train-good --good-policy kl"]},{"cell_type":"code","execution_count":null,"metadata":{"id":"MmX27cP0kq49"},"outputs":[],"source":["#! python experiments/train_KL_mode.py --exp-name exp18 --scenario simple_crypto --train-mode --train-adv --adv-policy kl --train-good --good-policy maddpg"]},{"cell_type":"code","execution_count":null,"metadata":{"id":"u025vZeI0Akn"},"outputs":[],"source":["#! python experiments/train_KL_mode.py --exp-name exp19 --scenario simple_push --train-mode --train-adv --adv-policy ddpg --train-good --good-policy ddpg"]},{"cell_type":"code","execution_count":null,"metadata":{"id":"-nLmHyeK0An5"},"outputs":[],"source":["#! python experiments/train_KL_mode.py --exp-name exp20 --scenario simple_push --train-mode --train-adv --adv-policy ddpg --train-good --good-policy kl"]},{"cell_type":"code","execution_count":null,"metadata":{"id":"lI2gAPeL0Ayw"},"outputs":[],"source":["#! python experiments/train_KL_mode.py --exp-name exp21 --scenario simple_push --train-mode --train-adv --adv-policy kl --train-good --good-policy ddpg"]},{"cell_type":"code","execution_count":null,"metadata":{"id":"DyclaMR6eLhk"},"outputs":[],"source":["#! python experiments/train_KL_mode.py --exp-name exp22 --scenario simple_spread --train-mode --train-adv --adv-policy ddpg --train-good --good-policy maddpg"]},{"cell_type":"code","execution_count":null,"metadata":{"id":"PM-b4oZteLsY"},"outputs":[],"source":["#! python experiments/train_KL_mode.py --exp-name exp23 --scenario simple_spread --train-mode --train-adv --adv-policy ddpg --train-good --good-policy kl"]},{"cell_type":"code","execution_count":null,"metadata":{"id":"o7YBXofneLz_"},"outputs":[],"source":["#! python experiments/train_KL_mode.py --exp-name exp24 --scenario simple_spread --train-mode --train-adv --adv-policy kl --train-good --good-policy maddpg"]},{"cell_type":"code","execution_count":null,"metadata":{"id":"w3oZJQJyJRTl"},"outputs":[],"source":["#! python experiments/train_KL_mode.py --exp-name exp25 --scenario simple_reference --train-mode --train-adv --adv-policy ddpg --train-good --good-policy maddpg"]},{"cell_type":"code","execution_count":null,"metadata":{"id":"DCNLd6E9JRcR"},"outputs":[],"source":["#! python experiments/train_KL_mode.py --exp-name exp26 --scenario simple_reference --train-mode --train-adv --adv-policy ddpg --train-good --good-policy kl"]},{"cell_type":"code","execution_count":null,"metadata":{"id":"SoEuwD1OJRkF"},"outputs":[],"source":["#! python experiments/train_KL_mode.py --exp-name exp27 --scenario simple_reference --train-mode --train-adv --adv-policy kl --train-good --good-policy maddpg"]},{"cell_type":"code","execution_count":null,"metadata":{"id":"pBes6FPXS261"},"outputs":[],"source":["#! python experiments/train_KL_mode.py --exp-name exp28 --scenario simple_tag --train-mode --train-adv --adv-policy ddpg --train-good --good-policy maddpg"]},{"cell_type":"code","execution_count":null,"metadata":{"id":"HqB_tYe2S3Cx"},"outputs":[],"source":["#! python experiments/train_KL_mode.py --exp-name exp29 --scenario simple_tag --train-mode --train-adv --adv-policy ddpg --train-good --good-policy kl"]},{"cell_type":"code","execution_count":null,"metadata":{"id":"vHriCWXJS3RO"},"outputs":[],"source":["#! python experiments/train_KL_mode.py --exp-name exp30 --scenario simple_tag --train-mode --train-adv --adv-policy kl --train-good --good-policy maddpg"]},{"cell_type":"code","execution_count":null,"metadata":{"colab":{"base_uri":"https://localhost:8080/"},"executionInfo":{"elapsed":6,"status":"ok","timestamp":1689209947600,"user":{"displayName":"Minxuan Duan","userId":"03763420385092998353"},"user_tz":300},"id":"MeTx4HyVuxZq","outputId":"88cf8d5c-2f2e-40a2-ecab-b02742ebd3fc"},"outputs":[{"name":"stdout","output_type":"stream","text":["shell-init: error retrieving current directory: getcwd: cannot access parent directories: Transport endpoint is not connected\n","shell-init: error retrieving current directory: getcwd: cannot access parent directories: Transport endpoint is not connected\n","python3: can't open file 'experiments/train_KL_mode.py': [Errno 107] Transport endpoint is not connected\n"]}],"source":["! python experiments/train_KL_mode.py --exp-name exp31 --scenario simple_world_comm --train-mode --train-adv --adv-policy ddpg --train-good --good-policy maddpg"]},{"cell_type":"code","execution_count":null,"metadata":{"colab":{"base_uri":"https://localhost:8080/"},"executionInfo":{"elapsed":151,"status":"ok","timestamp":1689209947747,"user":{"displayName":"Minxuan Duan","userId":"03763420385092998353"},"user_tz":300},"id":"0ZOOv_0Guxg8","outputId":"12486472-eb68-4f0c-ca4e-8bc2d97b438a"},"outputs":[{"name":"stdout","output_type":"stream","text":["shell-init: error retrieving current directory: getcwd: cannot access parent directories: Transport endpoint is not connected\n","shell-init: error retrieving current directory: getcwd: cannot access parent directories: Transport endpoint is not connected\n","python3: can't open file 'experiments/train_KL_mode.py': [Errno 107] Transport endpoint is not connected\n"]}],"source":["! python experiments/train_KL_mode.py --exp-name exp32 --scenario simple_world_comm --train-mode --train-adv --adv-policy ddpg --train-good --good-policy kl"]},{"cell_type":"code","execution_count":null,"metadata":{"colab":{"base_uri":"https://localhost:8080/"},"executionInfo":{"elapsed":120,"status":"ok","timestamp":1689209947864,"user":{"displayName":"Minxuan Duan","userId":"03763420385092998353"},"user_tz":300},"id":"VxCw9MvPuxl5","outputId":"8f74b331-9660-4e5c-f305-c7c2bdbf287e"},"outputs":[{"name":"stdout","output_type":"stream","text":["shell-init: error retrieving current directory: getcwd: cannot access parent directories: Transport endpoint is not connected\n","shell-init: error retrieving current directory: getcwd: cannot access parent directories: Transport endpoint is not connected\n","python3: can't open file 'experiments/train_KL_mode.py': [Errno 107] Transport endpoint is not connected\n"]}],"source":["! python experiments/train_KL_mode.py --exp-name exp33 --scenario simple_world_comm --train-mode --train-adv --adv-policy kl --train-good --good-policy maddpg"]},{"cell_type":"code","execution_count":null,"metadata":{"id":"iDzGtsi1vlvj"},"outputs":[],"source":["#! python experiments/train_KL_mode.py --exp-name exp34 --scenario simple_speaker_listener --train-mode --train-adv --adv-policy ddpg --train-good --good-policy maddpg"]},{"cell_type":"code","execution_count":null,"metadata":{"id":"FDX8j0L_vl3e"},"outputs":[],"source":["#! python experiments/train_KL_mode.py --exp-name exp35 --scenario simple_speaker_listener --train-mode --train-adv --adv-policy ddpg --train-good --good-policy kl"]},{"cell_type":"code","execution_count":null,"metadata":{"id":"XSV6Y8Ttvl-6"},"outputs":[],"source":["#! python experiments/train_KL_mode.py --exp-name exp36 --scenario simple_speaker_listener --train-mode --train-adv --adv-policy kl --train-good --good-policy maddpg"]},{"cell_type":"code","execution_count":null,"metadata":{"colab":{"base_uri":"https://localhost:8080/"},"executionInfo":{"elapsed":4925,"status":"ok","timestamp":1689227574181,"user":{"displayName":"Minxuan Duan","userId":"03763420385092998353"},"user_tz":300},"id":"IPf_ZKgBQgGL","outputId":"994b31fa-89a5-4b10-d76e-3a7aaf3288e9"},"outputs":[{"name":"stdout","output_type":"stream","text":["Requirement already satisfied: seaborn in /usr/local/lib/python3.10/dist-packages (0.12.2)\n","Requirement already satisfied: matplotlib in /usr/local/lib/python3.10/dist-packages (3.7.1)\n","Requirement already satisfied: numpy!=1.24.0,>=1.17 in /usr/local/lib/python3.10/dist-packages (from seaborn) (1.22.4)\n","Requirement already satisfied: pandas>=0.25 in /usr/local/lib/python3.10/dist-packages (from seaborn) (1.5.3)\n","Requirement already satisfied: contourpy>=1.0.1 in /usr/local/lib/python3.10/dist-packages (from matplotlib) (1.1.0)\n","Requirement already satisfied: cycler>=0.10 in /usr/local/lib/python3.10/dist-packages (from matplotlib) (0.11.0)\n","Requirement already satisfied: fonttools>=4.22.0 in /usr/local/lib/python3.10/dist-packages (from matplotlib) (4.40.0)\n","Requirement already satisfied: kiwisolver>=1.0.1 in /usr/local/lib/python3.10/dist-packages (from matplotlib) (1.4.4)\n","Requirement already satisfied: packaging>=20.0 in /usr/local/lib/python3.10/dist-packages (from matplotlib) (23.1)\n","Requirement already satisfied: pillow>=6.2.0 in /usr/local/lib/python3.10/dist-packages (from matplotlib) (8.4.0)\n","Requirement already satisfied: pyparsing>=2.3.1 in /usr/local/lib/python3.10/dist-packages (from matplotlib) (3.1.0)\n","Requirement already satisfied: python-dateutil>=2.7 in /usr/local/lib/python3.10/dist-packages (from matplotlib) (2.8.2)\n","Requirement already satisfied: pytz>=2020.1 in /usr/local/lib/python3.10/dist-packages (from pandas>=0.25->seaborn) (2022.7.1)\n","Requirement already satisfied: six>=1.5 in /usr/local/lib/python3.10/dist-packages (from python-dateutil>=2.7->matplotlib) (1.16.0)\n"]}],"source":["! pip install seaborn matplotlib"]},{"cell_type":"code","execution_count":null,"metadata":{"id":"EVanNo3JGN_q"},"outputs":[],"source":["import seaborn as sns\n","import matplotlib.pyplot as plt\n","import pickle\n","import matplotlib.cm as cm\n","\n","def plot_rewards_subplots(env_name, m, n, rewards_ddpg, rewards_adv_ddpg_good_kl, rewards_adv_kl_good_ddpg):\n","    x = [(i+1)*1000 for i in range(10)]\n","\n","    fig, axs = plt.subplots(1, 3, figsize=(18, 8))  # Create a new figure with 3 subplots\n","\n","    colors = cm.tab10(np.arange(10)/9.)  # Define colors for different agents\n","\n","    rewards = [rewards_ddpg, rewards_adv_ddpg_good_kl, rewards_adv_kl_good_ddpg]\n","    titles = ['DDPG VS DDPG', 'Adv: DDPG VS Good: OracleKL', 'Adv: OracleKL VS Good: DDPG']\n","\n","    for r in range(3):\n","        for i in range(m+n):\n","            if i < m:  # Plot Adv agent's rewards\n","                axs[r].plot(x, rewards[r][i*10:(i+1)*10], color=colors[i % len(colors)], label=f\"Adv Agent {i+1}\")\n","            else:  # Plot Good agent's rewards\n","                j = i - m\n","                axs[r].plot(x, rewards[r][i*10:(i+1)*10], color=colors[i % len(colors)], label=f\"Good Agent {j+1}\")\n","\n","        axs[r].set_title(f\"{env_name}: {titles[r]}\")  # Add a title to the subplot\n","        axs[r].set_xlabel(\"Time steps\")  # Add x-axis label\n","        axs[r].set_ylabel(\"Rewards\")  # Add y-axis label\n","        axs[r].legend()  # Show legend\n","\n","    plt.tight_layout()  # Ensure subplots do not overlap\n","    plt.savefig(env_name+'.eps')\n","    plt.show()  # Display the plot\n"]},{"cell_type":"code","execution_count":null,"metadata":{"colab":{"base_uri":"https://localhost:8080/"},"id":"LGlr3Kj1QMgb","outputId":"994b1bd6-f073-426c-dc94-5e7072108d08"},"outputs":[{"name":"stderr","output_type":"stream","text":["ERROR:root:Internal Python error in the inspect module.\n","Below is the traceback from this internal error.\n","\n","ERROR:root:Internal Python error in the inspect module.\n","Below is the traceback from this internal error.\n","\n"]},{"name":"stdout","output_type":"stream","text":["Traceback (most recent call last):\n","  File \"/usr/local/lib/python3.10/dist-packages/IPython/core/interactiveshell.py\", line 3553, in run_code\n","    exec(code_obj, self.user_global_ns, self.user_ns)\n","  File \"<ipython-input-73-f5a07539cd30>\", line 3, in <cell line: 3>\n","    x1 = pickle.load(open('exp14_agrewards.pkl', 'rb'))\n","NameError: name 'pickle' is not defined\n","\n","During handling of the above exception, another exception occurred:\n","\n","Traceback (most recent call last):\n","  File \"/usr/local/lib/python3.10/dist-packages/IPython/core/interactiveshell.py\", line 2099, in showtraceback\n","    stb = value._render_traceback_()\n","AttributeError: 'NameError' object has no attribute '_render_traceback_'\n","\n","During handling of the above exception, another exception occurred:\n","\n","Traceback (most recent call last):\n","  File \"/usr/local/lib/python3.10/dist-packages/IPython/core/ultratb.py\", line 1101, in get_records\n","    return _fixed_getinnerframes(etb, number_of_lines_of_context, tb_offset)\n","  File \"/usr/local/lib/python3.10/dist-packages/IPython/core/ultratb.py\", line 248, in wrapped\n","    return f(*args, **kwargs)\n","  File \"/usr/local/lib/python3.10/dist-packages/IPython/core/ultratb.py\", line 281, in _fixed_getinnerframes\n","    records = fix_frame_records_filenames(inspect.getinnerframes(etb, context))\n","  File \"/usr/lib/python3.10/inspect.py\", line 1662, in getinnerframes\n","    frameinfo = (tb.tb_frame,) + getframeinfo(tb, context)\n","  File \"/usr/lib/python3.10/inspect.py\", line 1620, in getframeinfo\n","    filename = getsourcefile(frame) or getfile(frame)\n","  File \"/usr/lib/python3.10/inspect.py\", line 829, in getsourcefile\n","    module = getmodule(object, filename)\n","  File \"/usr/lib/python3.10/inspect.py\", line 861, in getmodule\n","    file = getabsfile(object, _filename)\n","  File \"/usr/lib/python3.10/inspect.py\", line 845, in getabsfile\n","    return os.path.normcase(os.path.abspath(_filename))\n","  File \"/usr/lib/python3.10/posixpath.py\", line 384, in abspath\n","    cwd = os.getcwd()\n","OSError: [Errno 107] Transport endpoint is not connected\n","Traceback (most recent call last):\n","  File \"/usr/local/lib/python3.10/dist-packages/IPython/core/interactiveshell.py\", line 3553, in run_code\n","    exec(code_obj, self.user_global_ns, self.user_ns)\n","  File \"<ipython-input-73-f5a07539cd30>\", line 3, in <cell line: 3>\n","    x1 = pickle.load(open('exp14_agrewards.pkl', 'rb'))\n","NameError: name 'pickle' is not defined\n","\n","During handling of the above exception, another exception occurred:\n","\n","Traceback (most recent call last):\n","  File \"/usr/local/lib/python3.10/dist-packages/IPython/core/interactiveshell.py\", line 2099, in showtraceback\n","    stb = value._render_traceback_()\n","AttributeError: 'NameError' object has no attribute '_render_traceback_'\n","\n","During handling of the above exception, another exception occurred:\n","\n","Traceback (most recent call last):\n","  File \"/usr/local/lib/python3.10/dist-packages/IPython/core/interactiveshell.py\", line 3473, in run_ast_nodes\n","    if (await self.run_code(code, result,  async_=asy)):\n","  File \"/usr/local/lib/python3.10/dist-packages/IPython/core/interactiveshell.py\", line 3575, in run_code\n","    self.showtraceback(running_compiled_code=True)\n","  File \"/usr/local/lib/python3.10/dist-packages/IPython/core/interactiveshell.py\", line 2101, in showtraceback\n","    stb = self.InteractiveTB.structured_traceback(etype,\n","  File \"/usr/local/lib/python3.10/dist-packages/IPython/core/ultratb.py\", line 1367, in structured_traceback\n","    return FormattedTB.structured_traceback(\n","  File \"/usr/local/lib/python3.10/dist-packages/IPython/core/ultratb.py\", line 1267, in structured_traceback\n","    return VerboseTB.structured_traceback(\n","  File \"/usr/local/lib/python3.10/dist-packages/IPython/core/ultratb.py\", line 1124, in structured_traceback\n","    formatted_exception = self.format_exception_as_a_whole(etype, evalue, etb, number_of_lines_of_context,\n","  File \"/usr/local/lib/python3.10/dist-packages/IPython/core/ultratb.py\", line 1082, in format_exception_as_a_whole\n","    last_unique, recursion_repeat = find_recursion(orig_etype, evalue, records)\n","  File \"/usr/local/lib/python3.10/dist-packages/IPython/core/ultratb.py\", line 382, in find_recursion\n","    return len(records), 0\n","TypeError: object of type 'NoneType' has no len()\n","\n","During handling of the above exception, another exception occurred:\n","\n","Traceback (most recent call last):\n","  File \"/usr/local/lib/python3.10/dist-packages/IPython/core/interactiveshell.py\", line 2099, in showtraceback\n","    stb = value._render_traceback_()\n","AttributeError: 'TypeError' object has no attribute '_render_traceback_'\n","\n","During handling of the above exception, another exception occurred:\n","\n","Traceback (most recent call last):\n","  File \"/usr/local/lib/python3.10/dist-packages/IPython/core/ultratb.py\", line 1101, in get_records\n","    return _fixed_getinnerframes(etb, number_of_lines_of_context, tb_offset)\n","  File \"/usr/local/lib/python3.10/dist-packages/IPython/core/ultratb.py\", line 248, in wrapped\n","    return f(*args, **kwargs)\n","  File \"/usr/local/lib/python3.10/dist-packages/IPython/core/ultratb.py\", line 281, in _fixed_getinnerframes\n","    records = fix_frame_records_filenames(inspect.getinnerframes(etb, context))\n","  File \"/usr/lib/python3.10/inspect.py\", line 1662, in getinnerframes\n","    frameinfo = (tb.tb_frame,) + getframeinfo(tb, context)\n","  File \"/usr/lib/python3.10/inspect.py\", line 1620, in getframeinfo\n","    filename = getsourcefile(frame) or getfile(frame)\n","  File \"/usr/lib/python3.10/inspect.py\", line 829, in getsourcefile\n","    module = getmodule(object, filename)\n","  File \"/usr/lib/python3.10/inspect.py\", line 861, in getmodule\n","    file = getabsfile(object, _filename)\n","  File \"/usr/lib/python3.10/inspect.py\", line 845, in getabsfile\n","    return os.path.normcase(os.path.abspath(_filename))\n","  File \"/usr/lib/python3.10/posixpath.py\", line 384, in abspath\n","    cwd = os.getcwd()\n","OSError: [Errno 107] Transport endpoint is not connected\n"]},{"name":"stderr","output_type":"stream","text":["ERROR:root:Internal Python error in the inspect module.\n","Below is the traceback from this internal error.\n","\n"]},{"name":"stdout","output_type":"stream","text":["Traceback (most recent call last):\n","  File \"/usr/local/lib/python3.10/dist-packages/IPython/core/interactiveshell.py\", line 3553, in run_code\n","    exec(code_obj, self.user_global_ns, self.user_ns)\n","  File \"<ipython-input-73-f5a07539cd30>\", line 3, in <cell line: 3>\n","    x1 = pickle.load(open('exp14_agrewards.pkl', 'rb'))\n","NameError: name 'pickle' is not defined\n","\n","During handling of the above exception, another exception occurred:\n","\n","Traceback (most recent call last):\n","  File \"/usr/local/lib/python3.10/dist-packages/IPython/core/interactiveshell.py\", line 2099, in showtraceback\n","    stb = value._render_traceback_()\n","AttributeError: 'NameError' object has no attribute '_render_traceback_'\n","\n","During handling of the above exception, another exception occurred:\n","\n","Traceback (most recent call last):\n","  File \"/usr/local/lib/python3.10/dist-packages/IPython/core/interactiveshell.py\", line 3473, in run_ast_nodes\n","    if (await self.run_code(code, result,  async_=asy)):\n","  File \"/usr/local/lib/python3.10/dist-packages/IPython/core/interactiveshell.py\", line 3575, in run_code\n","    self.showtraceback(running_compiled_code=True)\n","  File \"/usr/local/lib/python3.10/dist-packages/IPython/core/interactiveshell.py\", line 2101, in showtraceback\n","    stb = self.InteractiveTB.structured_traceback(etype,\n","  File \"/usr/local/lib/python3.10/dist-packages/IPython/core/ultratb.py\", line 1367, in structured_traceback\n","    return FormattedTB.structured_traceback(\n","  File \"/usr/local/lib/python3.10/dist-packages/IPython/core/ultratb.py\", line 1267, in structured_traceback\n","    return VerboseTB.structured_traceback(\n","  File \"/usr/local/lib/python3.10/dist-packages/IPython/core/ultratb.py\", line 1124, in structured_traceback\n","    formatted_exception = self.format_exception_as_a_whole(etype, evalue, etb, number_of_lines_of_context,\n","  File \"/usr/local/lib/python3.10/dist-packages/IPython/core/ultratb.py\", line 1082, in format_exception_as_a_whole\n","    last_unique, recursion_repeat = find_recursion(orig_etype, evalue, records)\n","  File \"/usr/local/lib/python3.10/dist-packages/IPython/core/ultratb.py\", line 382, in find_recursion\n","    return len(records), 0\n","TypeError: object of type 'NoneType' has no len()\n","\n","During handling of the above exception, another exception occurred:\n","\n","Traceback (most recent call last):\n","  File \"/usr/local/lib/python3.10/dist-packages/IPython/core/interactiveshell.py\", line 2099, in showtraceback\n","    stb = value._render_traceback_()\n","AttributeError: 'TypeError' object has no attribute '_render_traceback_'\n","\n","During handling of the above exception, another exception occurred:\n","\n","Traceback (most recent call last):\n","  File \"/usr/local/lib/python3.10/dist-packages/IPython/core/interactiveshell.py\", line 3030, in _run_cell\n","    return runner(coro)\n","  File \"/usr/local/lib/python3.10/dist-packages/IPython/core/async_helpers.py\", line 78, in _pseudo_sync_runner\n","    coro.send(None)\n","  File \"/usr/local/lib/python3.10/dist-packages/IPython/core/interactiveshell.py\", line 3257, in run_cell_async\n","    has_raised = await self.run_ast_nodes(code_ast.body, cell_name,\n","  File \"/usr/local/lib/python3.10/dist-packages/IPython/core/interactiveshell.py\", line 3492, in run_ast_nodes\n","    self.showtraceback()\n","  File \"/usr/local/lib/python3.10/dist-packages/IPython/core/interactiveshell.py\", line 2101, in showtraceback\n","    stb = self.InteractiveTB.structured_traceback(etype,\n","  File \"/usr/local/lib/python3.10/dist-packages/IPython/core/ultratb.py\", line 1367, in structured_traceback\n","    return FormattedTB.structured_traceback(\n","  File \"/usr/local/lib/python3.10/dist-packages/IPython/core/ultratb.py\", line 1267, in structured_traceback\n","    return VerboseTB.structured_traceback(\n","  File \"/usr/local/lib/python3.10/dist-packages/IPython/core/ultratb.py\", line 1142, in structured_traceback\n","    formatted_exceptions += self.format_exception_as_a_whole(etype, evalue, etb, lines_of_context,\n","  File \"/usr/local/lib/python3.10/dist-packages/IPython/core/ultratb.py\", line 1082, in format_exception_as_a_whole\n","    last_unique, recursion_repeat = find_recursion(orig_etype, evalue, records)\n","  File \"/usr/local/lib/python3.10/dist-packages/IPython/core/ultratb.py\", line 382, in find_recursion\n","    return len(records), 0\n","TypeError: object of type 'NoneType' has no len()\n","\n","During handling of the above exception, another exception occurred:\n","\n","Traceback (most recent call last):\n","  File \"/usr/local/lib/python3.10/dist-packages/IPython/core/interactiveshell.py\", line 2099, in showtraceback\n","    stb = value._render_traceback_()\n","AttributeError: 'TypeError' object has no attribute '_render_traceback_'\n","\n","During handling of the above exception, another exception occurred:\n","\n","Traceback (most recent call last):\n","  File \"/usr/local/lib/python3.10/dist-packages/IPython/core/ultratb.py\", line 1101, in get_records\n","    return _fixed_getinnerframes(etb, number_of_lines_of_context, tb_offset)\n","  File \"/usr/local/lib/python3.10/dist-packages/IPython/core/ultratb.py\", line 248, in wrapped\n","    return f(*args, **kwargs)\n","  File \"/usr/local/lib/python3.10/dist-packages/IPython/core/ultratb.py\", line 281, in _fixed_getinnerframes\n","    records = fix_frame_records_filenames(inspect.getinnerframes(etb, context))\n","  File \"/usr/lib/python3.10/inspect.py\", line 1662, in getinnerframes\n","    frameinfo = (tb.tb_frame,) + getframeinfo(tb, context)\n","  File \"/usr/lib/python3.10/inspect.py\", line 1620, in getframeinfo\n","    filename = getsourcefile(frame) or getfile(frame)\n","  File \"/usr/lib/python3.10/inspect.py\", line 829, in getsourcefile\n","    module = getmodule(object, filename)\n","  File \"/usr/lib/python3.10/inspect.py\", line 861, in getmodule\n","    file = getabsfile(object, _filename)\n","  File \"/usr/lib/python3.10/inspect.py\", line 845, in getabsfile\n","    return os.path.normcase(os.path.abspath(_filename))\n","  File \"/usr/lib/python3.10/posixpath.py\", line 384, in abspath\n","    cwd = os.getcwd()\n","OSError: [Errno 107] Transport endpoint is not connected\n"]}],"source":["import numpy as np\n","\n","x1 = pickle.load(open('exp14_agrewards.pkl', 'rb'))\n","x2 = pickle.load(open('exp15_agrewards.pkl', 'rb'))\n","x3 = pickle.load(open('exp13_agrewards.pkl', 'rb'))\n","\n","plot_rewards_subplots('simple_adversary', 1, 2, x1, x2, x3)"]},{"cell_type":"code","execution_count":null,"metadata":{"colab":{"base_uri":"https://localhost:8080/"},"id":"7amoMPN8Q3y-","outputId":"2cdb2617-a4fa-4074-f898-4d030e2611ee"},"outputs":[{"name":"stderr","output_type":"stream","text":["ERROR:root:Internal Python error in the inspect module.\n","Below is the traceback from this internal error.\n","\n"]},{"name":"stdout","output_type":"stream","text":["Traceback (most recent call last):\n","  File \"/usr/local/lib/python3.10/dist-packages/IPython/core/interactiveshell.py\", line 3553, in run_code\n","    exec(code_obj, self.user_global_ns, self.user_ns)\n","  File \"<ipython-input-73-53b0d2715120>\", line 1, in <cell line: 1>\n","    x1 = pickle.load(open('exp16_agrewards.pkl', 'rb'))\n","NameError: name 'pickle' is not defined\n","\n","During handling of the above exception, another exception occurred:\n","\n","Traceback (most recent call last):\n","  File \"/usr/local/lib/python3.10/dist-packages/IPython/core/interactiveshell.py\", line 2099, in showtraceback\n","    stb = value._render_traceback_()\n","AttributeError: 'NameError' object has no attribute '_render_traceback_'\n","\n","During handling of the above exception, another exception occurred:\n","\n","Traceback (most recent call last):\n","  File \"/usr/local/lib/python3.10/dist-packages/IPython/core/ultratb.py\", line 1101, in get_records\n","    return _fixed_getinnerframes(etb, number_of_lines_of_context, tb_offset)\n","  File \"/usr/local/lib/python3.10/dist-packages/IPython/core/ultratb.py\", line 248, in wrapped\n","    return f(*args, **kwargs)\n","  File \"/usr/local/lib/python3.10/dist-packages/IPython/core/ultratb.py\", line 281, in _fixed_getinnerframes\n","    records = fix_frame_records_filenames(inspect.getinnerframes(etb, context))\n","  File \"/usr/lib/python3.10/inspect.py\", line 1662, in getinnerframes\n","    frameinfo = (tb.tb_frame,) + getframeinfo(tb, context)\n","  File \"/usr/lib/python3.10/inspect.py\", line 1620, in getframeinfo\n","    filename = getsourcefile(frame) or getfile(frame)\n","  File \"/usr/lib/python3.10/inspect.py\", line 829, in getsourcefile\n","    module = getmodule(object, filename)\n","  File \"/usr/lib/python3.10/inspect.py\", line 861, in getmodule\n","    file = getabsfile(object, _filename)\n","  File \"/usr/lib/python3.10/inspect.py\", line 845, in getabsfile\n","    return os.path.normcase(os.path.abspath(_filename))\n","  File \"/usr/lib/python3.10/posixpath.py\", line 384, in abspath\n","    cwd = os.getcwd()\n","OSError: [Errno 107] Transport endpoint is not connected\n"]},{"name":"stderr","output_type":"stream","text":["ERROR:root:Internal Python error in the inspect module.\n","Below is the traceback from this internal error.\n","\n","ERROR:root:Internal Python error in the inspect module.\n","Below is the traceback from this internal error.\n","\n"]},{"name":"stdout","output_type":"stream","text":["Traceback (most recent call last):\n","  File \"/usr/local/lib/python3.10/dist-packages/IPython/core/interactiveshell.py\", line 3553, in run_code\n","    exec(code_obj, self.user_global_ns, self.user_ns)\n","  File \"<ipython-input-73-53b0d2715120>\", line 1, in <cell line: 1>\n","    x1 = pickle.load(open('exp16_agrewards.pkl', 'rb'))\n","NameError: name 'pickle' is not defined\n","\n","During handling of the above exception, another exception occurred:\n","\n","Traceback (most recent call last):\n","  File \"/usr/local/lib/python3.10/dist-packages/IPython/core/interactiveshell.py\", line 2099, in showtraceback\n","    stb = value._render_traceback_()\n","AttributeError: 'NameError' object has no attribute '_render_traceback_'\n","\n","During handling of the above exception, another exception occurred:\n","\n","Traceback (most recent call last):\n","  File \"/usr/local/lib/python3.10/dist-packages/IPython/core/interactiveshell.py\", line 3473, in run_ast_nodes\n","    if (await self.run_code(code, result,  async_=asy)):\n","  File \"/usr/local/lib/python3.10/dist-packages/IPython/core/interactiveshell.py\", line 3575, in run_code\n","    self.showtraceback(running_compiled_code=True)\n","  File \"/usr/local/lib/python3.10/dist-packages/IPython/core/interactiveshell.py\", line 2101, in showtraceback\n","    stb = self.InteractiveTB.structured_traceback(etype,\n","  File \"/usr/local/lib/python3.10/dist-packages/IPython/core/ultratb.py\", line 1367, in structured_traceback\n","    return FormattedTB.structured_traceback(\n","  File \"/usr/local/lib/python3.10/dist-packages/IPython/core/ultratb.py\", line 1267, in structured_traceback\n","    return VerboseTB.structured_traceback(\n","  File \"/usr/local/lib/python3.10/dist-packages/IPython/core/ultratb.py\", line 1124, in structured_traceback\n","    formatted_exception = self.format_exception_as_a_whole(etype, evalue, etb, number_of_lines_of_context,\n","  File \"/usr/local/lib/python3.10/dist-packages/IPython/core/ultratb.py\", line 1082, in format_exception_as_a_whole\n","    last_unique, recursion_repeat = find_recursion(orig_etype, evalue, records)\n","  File \"/usr/local/lib/python3.10/dist-packages/IPython/core/ultratb.py\", line 382, in find_recursion\n","    return len(records), 0\n","TypeError: object of type 'NoneType' has no len()\n","\n","During handling of the above exception, another exception occurred:\n","\n","Traceback (most recent call last):\n","  File \"/usr/local/lib/python3.10/dist-packages/IPython/core/interactiveshell.py\", line 2099, in showtraceback\n","    stb = value._render_traceback_()\n","AttributeError: 'TypeError' object has no attribute '_render_traceback_'\n","\n","During handling of the above exception, another exception occurred:\n","\n","Traceback (most recent call last):\n","  File \"/usr/local/lib/python3.10/dist-packages/IPython/core/ultratb.py\", line 1101, in get_records\n","    return _fixed_getinnerframes(etb, number_of_lines_of_context, tb_offset)\n","  File \"/usr/local/lib/python3.10/dist-packages/IPython/core/ultratb.py\", line 248, in wrapped\n","    return f(*args, **kwargs)\n","  File \"/usr/local/lib/python3.10/dist-packages/IPython/core/ultratb.py\", line 281, in _fixed_getinnerframes\n","    records = fix_frame_records_filenames(inspect.getinnerframes(etb, context))\n","  File \"/usr/lib/python3.10/inspect.py\", line 1662, in getinnerframes\n","    frameinfo = (tb.tb_frame,) + getframeinfo(tb, context)\n","  File \"/usr/lib/python3.10/inspect.py\", line 1620, in getframeinfo\n","    filename = getsourcefile(frame) or getfile(frame)\n","  File \"/usr/lib/python3.10/inspect.py\", line 829, in getsourcefile\n","    module = getmodule(object, filename)\n","  File \"/usr/lib/python3.10/inspect.py\", line 861, in getmodule\n","    file = getabsfile(object, _filename)\n","  File \"/usr/lib/python3.10/inspect.py\", line 845, in getabsfile\n","    return os.path.normcase(os.path.abspath(_filename))\n","  File \"/usr/lib/python3.10/posixpath.py\", line 384, in abspath\n","    cwd = os.getcwd()\n","OSError: [Errno 107] Transport endpoint is not connected\n","Traceback (most recent call last):\n","  File \"/usr/local/lib/python3.10/dist-packages/IPython/core/interactiveshell.py\", line 3553, in run_code\n","    exec(code_obj, self.user_global_ns, self.user_ns)\n","  File \"<ipython-input-73-53b0d2715120>\", line 1, in <cell line: 1>\n","    x1 = pickle.load(open('exp16_agrewards.pkl', 'rb'))\n","NameError: name 'pickle' is not defined\n","\n","During handling of the above exception, another exception occurred:\n","\n","Traceback (most recent call last):\n","  File \"/usr/local/lib/python3.10/dist-packages/IPython/core/interactiveshell.py\", line 2099, in showtraceback\n","    stb = value._render_traceback_()\n","AttributeError: 'NameError' object has no attribute '_render_traceback_'\n","\n","During handling of the above exception, another exception occurred:\n","\n","Traceback (most recent call last):\n","  File \"/usr/local/lib/python3.10/dist-packages/IPython/core/interactiveshell.py\", line 3473, in run_ast_nodes\n","    if (await self.run_code(code, result,  async_=asy)):\n","  File \"/usr/local/lib/python3.10/dist-packages/IPython/core/interactiveshell.py\", line 3575, in run_code\n","    self.showtraceback(running_compiled_code=True)\n","  File \"/usr/local/lib/python3.10/dist-packages/IPython/core/interactiveshell.py\", line 2101, in showtraceback\n","    stb = self.InteractiveTB.structured_traceback(etype,\n","  File \"/usr/local/lib/python3.10/dist-packages/IPython/core/ultratb.py\", line 1367, in structured_traceback\n","    return FormattedTB.structured_traceback(\n","  File \"/usr/local/lib/python3.10/dist-packages/IPython/core/ultratb.py\", line 1267, in structured_traceback\n","    return VerboseTB.structured_traceback(\n","  File \"/usr/local/lib/python3.10/dist-packages/IPython/core/ultratb.py\", line 1124, in structured_traceback\n","    formatted_exception = self.format_exception_as_a_whole(etype, evalue, etb, number_of_lines_of_context,\n","  File \"/usr/local/lib/python3.10/dist-packages/IPython/core/ultratb.py\", line 1082, in format_exception_as_a_whole\n","    last_unique, recursion_repeat = find_recursion(orig_etype, evalue, records)\n","  File \"/usr/local/lib/python3.10/dist-packages/IPython/core/ultratb.py\", line 382, in find_recursion\n","    return len(records), 0\n","TypeError: object of type 'NoneType' has no len()\n","\n","During handling of the above exception, another exception occurred:\n","\n","Traceback (most recent call last):\n","  File \"/usr/local/lib/python3.10/dist-packages/IPython/core/interactiveshell.py\", line 2099, in showtraceback\n","    stb = value._render_traceback_()\n","AttributeError: 'TypeError' object has no attribute '_render_traceback_'\n","\n","During handling of the above exception, another exception occurred:\n","\n","Traceback (most recent call last):\n","  File \"/usr/local/lib/python3.10/dist-packages/IPython/core/interactiveshell.py\", line 3030, in _run_cell\n","    return runner(coro)\n","  File \"/usr/local/lib/python3.10/dist-packages/IPython/core/async_helpers.py\", line 78, in _pseudo_sync_runner\n","    coro.send(None)\n","  File \"/usr/local/lib/python3.10/dist-packages/IPython/core/interactiveshell.py\", line 3257, in run_cell_async\n","    has_raised = await self.run_ast_nodes(code_ast.body, cell_name,\n","  File \"/usr/local/lib/python3.10/dist-packages/IPython/core/interactiveshell.py\", line 3492, in run_ast_nodes\n","    self.showtraceback()\n","  File \"/usr/local/lib/python3.10/dist-packages/IPython/core/interactiveshell.py\", line 2101, in showtraceback\n","    stb = self.InteractiveTB.structured_traceback(etype,\n","  File \"/usr/local/lib/python3.10/dist-packages/IPython/core/ultratb.py\", line 1367, in structured_traceback\n","    return FormattedTB.structured_traceback(\n","  File \"/usr/local/lib/python3.10/dist-packages/IPython/core/ultratb.py\", line 1267, in structured_traceback\n","    return VerboseTB.structured_traceback(\n","  File \"/usr/local/lib/python3.10/dist-packages/IPython/core/ultratb.py\", line 1142, in structured_traceback\n","    formatted_exceptions += self.format_exception_as_a_whole(etype, evalue, etb, lines_of_context,\n","  File \"/usr/local/lib/python3.10/dist-packages/IPython/core/ultratb.py\", line 1082, in format_exception_as_a_whole\n","    last_unique, recursion_repeat = find_recursion(orig_etype, evalue, records)\n","  File \"/usr/local/lib/python3.10/dist-packages/IPython/core/ultratb.py\", line 382, in find_recursion\n","    return len(records), 0\n","TypeError: object of type 'NoneType' has no len()\n","\n","During handling of the above exception, another exception occurred:\n","\n","Traceback (most recent call last):\n","  File \"/usr/local/lib/python3.10/dist-packages/IPython/core/interactiveshell.py\", line 2099, in showtraceback\n","    stb = value._render_traceback_()\n","AttributeError: 'TypeError' object has no attribute '_render_traceback_'\n","\n","During handling of the above exception, another exception occurred:\n","\n","Traceback (most recent call last):\n","  File \"/usr/local/lib/python3.10/dist-packages/IPython/core/ultratb.py\", line 1101, in get_records\n","    return _fixed_getinnerframes(etb, number_of_lines_of_context, tb_offset)\n","  File \"/usr/local/lib/python3.10/dist-packages/IPython/core/ultratb.py\", line 248, in wrapped\n","    return f(*args, **kwargs)\n","  File \"/usr/local/lib/python3.10/dist-packages/IPython/core/ultratb.py\", line 281, in _fixed_getinnerframes\n","    records = fix_frame_records_filenames(inspect.getinnerframes(etb, context))\n","  File \"/usr/lib/python3.10/inspect.py\", line 1662, in getinnerframes\n","    frameinfo = (tb.tb_frame,) + getframeinfo(tb, context)\n","  File \"/usr/lib/python3.10/inspect.py\", line 1620, in getframeinfo\n","    filename = getsourcefile(frame) or getfile(frame)\n","  File \"/usr/lib/python3.10/inspect.py\", line 829, in getsourcefile\n","    module = getmodule(object, filename)\n","  File \"/usr/lib/python3.10/inspect.py\", line 861, in getmodule\n","    file = getabsfile(object, _filename)\n","  File \"/usr/lib/python3.10/inspect.py\", line 845, in getabsfile\n","    return os.path.normcase(os.path.abspath(_filename))\n","  File \"/usr/lib/python3.10/posixpath.py\", line 384, in abspath\n","    cwd = os.getcwd()\n","OSError: [Errno 107] Transport endpoint is not connected\n"]}],"source":["x1 = pickle.load(open('exp16_agrewards.pkl', 'rb'))\n","x2 = pickle.load(open('exp17_agrewards.pkl', 'rb'))\n","x3 = pickle.load(open('exp18_agrewards.pkl', 'rb'))\n","\n","plot_rewards_subplots('simple_crypto', 1, 2, x1, x2, x3)"]},{"cell_type":"code","execution_count":null,"metadata":{"colab":{"base_uri":"https://localhost:8080/"},"id":"Ps2dWGjuLKJN","outputId":"d640d46d-7687-4092-aa7b-f3f4016dc5ed"},"outputs":[{"name":"stderr","output_type":"stream","text":["ERROR:root:Internal Python error in the inspect module.\n","Below is the traceback from this internal error.\n","\n","ERROR:root:Internal Python error in the inspect module.\n","Below is the traceback from this internal error.\n","\n"]},{"name":"stdout","output_type":"stream","text":["Traceback (most recent call last):\n","  File \"/usr/local/lib/python3.10/dist-packages/IPython/core/interactiveshell.py\", line 3553, in run_code\n","    exec(code_obj, self.user_global_ns, self.user_ns)\n","  File \"<ipython-input-73-4219145ef24b>\", line 1, in <cell line: 1>\n","    x1 = pickle.load(open('exp19_agrewards.pkl', 'rb'))\n","NameError: name 'pickle' is not defined\n","\n","During handling of the above exception, another exception occurred:\n","\n","Traceback (most recent call last):\n","  File \"/usr/local/lib/python3.10/dist-packages/IPython/core/interactiveshell.py\", line 2099, in showtraceback\n","    stb = value._render_traceback_()\n","AttributeError: 'NameError' object has no attribute '_render_traceback_'\n","\n","During handling of the above exception, another exception occurred:\n","\n","Traceback (most recent call last):\n","  File \"/usr/local/lib/python3.10/dist-packages/IPython/core/ultratb.py\", line 1101, in get_records\n","    return _fixed_getinnerframes(etb, number_of_lines_of_context, tb_offset)\n","  File \"/usr/local/lib/python3.10/dist-packages/IPython/core/ultratb.py\", line 248, in wrapped\n","    return f(*args, **kwargs)\n","  File \"/usr/local/lib/python3.10/dist-packages/IPython/core/ultratb.py\", line 281, in _fixed_getinnerframes\n","    records = fix_frame_records_filenames(inspect.getinnerframes(etb, context))\n","  File \"/usr/lib/python3.10/inspect.py\", line 1662, in getinnerframes\n","    frameinfo = (tb.tb_frame,) + getframeinfo(tb, context)\n","  File \"/usr/lib/python3.10/inspect.py\", line 1620, in getframeinfo\n","    filename = getsourcefile(frame) or getfile(frame)\n","  File \"/usr/lib/python3.10/inspect.py\", line 829, in getsourcefile\n","    module = getmodule(object, filename)\n","  File \"/usr/lib/python3.10/inspect.py\", line 861, in getmodule\n","    file = getabsfile(object, _filename)\n","  File \"/usr/lib/python3.10/inspect.py\", line 845, in getabsfile\n","    return os.path.normcase(os.path.abspath(_filename))\n","  File \"/usr/lib/python3.10/posixpath.py\", line 384, in abspath\n","    cwd = os.getcwd()\n","OSError: [Errno 107] Transport endpoint is not connected\n","Traceback (most recent call last):\n","  File \"/usr/local/lib/python3.10/dist-packages/IPython/core/interactiveshell.py\", line 3553, in run_code\n","    exec(code_obj, self.user_global_ns, self.user_ns)\n","  File \"<ipython-input-73-4219145ef24b>\", line 1, in <cell line: 1>\n","    x1 = pickle.load(open('exp19_agrewards.pkl', 'rb'))\n","NameError: name 'pickle' is not defined\n","\n","During handling of the above exception, another exception occurred:\n","\n","Traceback (most recent call last):\n","  File \"/usr/local/lib/python3.10/dist-packages/IPython/core/interactiveshell.py\", line 2099, in showtraceback\n","    stb = value._render_traceback_()\n","AttributeError: 'NameError' object has no attribute '_render_traceback_'\n","\n","During handling of the above exception, another exception occurred:\n","\n","Traceback (most recent call last):\n","  File \"/usr/local/lib/python3.10/dist-packages/IPython/core/interactiveshell.py\", line 3473, in run_ast_nodes\n","    if (await self.run_code(code, result,  async_=asy)):\n","  File \"/usr/local/lib/python3.10/dist-packages/IPython/core/interactiveshell.py\", line 3575, in run_code\n","    self.showtraceback(running_compiled_code=True)\n","  File \"/usr/local/lib/python3.10/dist-packages/IPython/core/interactiveshell.py\", line 2101, in showtraceback\n","    stb = self.InteractiveTB.structured_traceback(etype,\n","  File \"/usr/local/lib/python3.10/dist-packages/IPython/core/ultratb.py\", line 1367, in structured_traceback\n","    return FormattedTB.structured_traceback(\n","  File \"/usr/local/lib/python3.10/dist-packages/IPython/core/ultratb.py\", line 1267, in structured_traceback\n","    return VerboseTB.structured_traceback(\n","  File \"/usr/local/lib/python3.10/dist-packages/IPython/core/ultratb.py\", line 1124, in structured_traceback\n","    formatted_exception = self.format_exception_as_a_whole(etype, evalue, etb, number_of_lines_of_context,\n","  File \"/usr/local/lib/python3.10/dist-packages/IPython/core/ultratb.py\", line 1082, in format_exception_as_a_whole\n","    last_unique, recursion_repeat = find_recursion(orig_etype, evalue, records)\n","  File \"/usr/local/lib/python3.10/dist-packages/IPython/core/ultratb.py\", line 382, in find_recursion\n","    return len(records), 0\n","TypeError: object of type 'NoneType' has no len()\n","\n","During handling of the above exception, another exception occurred:\n","\n","Traceback (most recent call last):\n","  File \"/usr/local/lib/python3.10/dist-packages/IPython/core/interactiveshell.py\", line 2099, in showtraceback\n","    stb = value._render_traceback_()\n","AttributeError: 'TypeError' object has no attribute '_render_traceback_'\n","\n","During handling of the above exception, another exception occurred:\n","\n","Traceback (most recent call last):\n","  File \"/usr/local/lib/python3.10/dist-packages/IPython/core/ultratb.py\", line 1101, in get_records\n","    return _fixed_getinnerframes(etb, number_of_lines_of_context, tb_offset)\n","  File \"/usr/local/lib/python3.10/dist-packages/IPython/core/ultratb.py\", line 248, in wrapped\n","    return f(*args, **kwargs)\n","  File \"/usr/local/lib/python3.10/dist-packages/IPython/core/ultratb.py\", line 281, in _fixed_getinnerframes\n","    records = fix_frame_records_filenames(inspect.getinnerframes(etb, context))\n","  File \"/usr/lib/python3.10/inspect.py\", line 1662, in getinnerframes\n","    frameinfo = (tb.tb_frame,) + getframeinfo(tb, context)\n","  File \"/usr/lib/python3.10/inspect.py\", line 1620, in getframeinfo\n","    filename = getsourcefile(frame) or getfile(frame)\n","  File \"/usr/lib/python3.10/inspect.py\", line 829, in getsourcefile\n","    module = getmodule(object, filename)\n","  File \"/usr/lib/python3.10/inspect.py\", line 861, in getmodule\n","    file = getabsfile(object, _filename)\n","  File \"/usr/lib/python3.10/inspect.py\", line 845, in getabsfile\n","    return os.path.normcase(os.path.abspath(_filename))\n","  File \"/usr/lib/python3.10/posixpath.py\", line 384, in abspath\n","    cwd = os.getcwd()\n","OSError: [Errno 107] Transport endpoint is not connected\n"]},{"name":"stderr","output_type":"stream","text":["ERROR:root:Internal Python error in the inspect module.\n","Below is the traceback from this internal error.\n","\n"]},{"name":"stdout","output_type":"stream","text":["Traceback (most recent call last):\n","  File \"/usr/local/lib/python3.10/dist-packages/IPython/core/interactiveshell.py\", line 3553, in run_code\n","    exec(code_obj, self.user_global_ns, self.user_ns)\n","  File \"<ipython-input-73-4219145ef24b>\", line 1, in <cell line: 1>\n","    x1 = pickle.load(open('exp19_agrewards.pkl', 'rb'))\n","NameError: name 'pickle' is not defined\n","\n","During handling of the above exception, another exception occurred:\n","\n","Traceback (most recent call last):\n","  File \"/usr/local/lib/python3.10/dist-packages/IPython/core/interactiveshell.py\", line 2099, in showtraceback\n","    stb = value._render_traceback_()\n","AttributeError: 'NameError' object has no attribute '_render_traceback_'\n","\n","During handling of the above exception, another exception occurred:\n","\n","Traceback (most recent call last):\n","  File \"/usr/local/lib/python3.10/dist-packages/IPython/core/interactiveshell.py\", line 3473, in run_ast_nodes\n","    if (await self.run_code(code, result,  async_=asy)):\n","  File \"/usr/local/lib/python3.10/dist-packages/IPython/core/interactiveshell.py\", line 3575, in run_code\n","    self.showtraceback(running_compiled_code=True)\n","  File \"/usr/local/lib/python3.10/dist-packages/IPython/core/interactiveshell.py\", line 2101, in showtraceback\n","    stb = self.InteractiveTB.structured_traceback(etype,\n","  File \"/usr/local/lib/python3.10/dist-packages/IPython/core/ultratb.py\", line 1367, in structured_traceback\n","    return FormattedTB.structured_traceback(\n","  File \"/usr/local/lib/python3.10/dist-packages/IPython/core/ultratb.py\", line 1267, in structured_traceback\n","    return VerboseTB.structured_traceback(\n","  File \"/usr/local/lib/python3.10/dist-packages/IPython/core/ultratb.py\", line 1124, in structured_traceback\n","    formatted_exception = self.format_exception_as_a_whole(etype, evalue, etb, number_of_lines_of_context,\n","  File \"/usr/local/lib/python3.10/dist-packages/IPython/core/ultratb.py\", line 1082, in format_exception_as_a_whole\n","    last_unique, recursion_repeat = find_recursion(orig_etype, evalue, records)\n","  File \"/usr/local/lib/python3.10/dist-packages/IPython/core/ultratb.py\", line 382, in find_recursion\n","    return len(records), 0\n","TypeError: object of type 'NoneType' has no len()\n","\n","During handling of the above exception, another exception occurred:\n","\n","Traceback (most recent call last):\n","  File \"/usr/local/lib/python3.10/dist-packages/IPython/core/interactiveshell.py\", line 2099, in showtraceback\n","    stb = value._render_traceback_()\n","AttributeError: 'TypeError' object has no attribute '_render_traceback_'\n","\n","During handling of the above exception, another exception occurred:\n","\n","Traceback (most recent call last):\n","  File \"/usr/local/lib/python3.10/dist-packages/IPython/core/interactiveshell.py\", line 3030, in _run_cell\n","    return runner(coro)\n","  File \"/usr/local/lib/python3.10/dist-packages/IPython/core/async_helpers.py\", line 78, in _pseudo_sync_runner\n","    coro.send(None)\n","  File \"/usr/local/lib/python3.10/dist-packages/IPython/core/interactiveshell.py\", line 3257, in run_cell_async\n","    has_raised = await self.run_ast_nodes(code_ast.body, cell_name,\n","  File \"/usr/local/lib/python3.10/dist-packages/IPython/core/interactiveshell.py\", line 3492, in run_ast_nodes\n","    self.showtraceback()\n","  File \"/usr/local/lib/python3.10/dist-packages/IPython/core/interactiveshell.py\", line 2101, in showtraceback\n","    stb = self.InteractiveTB.structured_traceback(etype,\n","  File \"/usr/local/lib/python3.10/dist-packages/IPython/core/ultratb.py\", line 1367, in structured_traceback\n","    return FormattedTB.structured_traceback(\n","  File \"/usr/local/lib/python3.10/dist-packages/IPython/core/ultratb.py\", line 1267, in structured_traceback\n","    return VerboseTB.structured_traceback(\n","  File \"/usr/local/lib/python3.10/dist-packages/IPython/core/ultratb.py\", line 1142, in structured_traceback\n","    formatted_exceptions += self.format_exception_as_a_whole(etype, evalue, etb, lines_of_context,\n","  File \"/usr/local/lib/python3.10/dist-packages/IPython/core/ultratb.py\", line 1082, in format_exception_as_a_whole\n","    last_unique, recursion_repeat = find_recursion(orig_etype, evalue, records)\n","  File \"/usr/local/lib/python3.10/dist-packages/IPython/core/ultratb.py\", line 382, in find_recursion\n","    return len(records), 0\n","TypeError: object of type 'NoneType' has no len()\n","\n","During handling of the above exception, another exception occurred:\n","\n","Traceback (most recent call last):\n","  File \"/usr/local/lib/python3.10/dist-packages/IPython/core/interactiveshell.py\", line 2099, in showtraceback\n","    stb = value._render_traceback_()\n","AttributeError: 'TypeError' object has no attribute '_render_traceback_'\n","\n","During handling of the above exception, another exception occurred:\n","\n","Traceback (most recent call last):\n","  File \"/usr/local/lib/python3.10/dist-packages/IPython/core/ultratb.py\", line 1101, in get_records\n","    return _fixed_getinnerframes(etb, number_of_lines_of_context, tb_offset)\n","  File \"/usr/local/lib/python3.10/dist-packages/IPython/core/ultratb.py\", line 248, in wrapped\n","    return f(*args, **kwargs)\n","  File \"/usr/local/lib/python3.10/dist-packages/IPython/core/ultratb.py\", line 281, in _fixed_getinnerframes\n","    records = fix_frame_records_filenames(inspect.getinnerframes(etb, context))\n","  File \"/usr/lib/python3.10/inspect.py\", line 1662, in getinnerframes\n","    frameinfo = (tb.tb_frame,) + getframeinfo(tb, context)\n","  File \"/usr/lib/python3.10/inspect.py\", line 1620, in getframeinfo\n","    filename = getsourcefile(frame) or getfile(frame)\n","  File \"/usr/lib/python3.10/inspect.py\", line 829, in getsourcefile\n","    module = getmodule(object, filename)\n","  File \"/usr/lib/python3.10/inspect.py\", line 861, in getmodule\n","    file = getabsfile(object, _filename)\n","  File \"/usr/lib/python3.10/inspect.py\", line 845, in getabsfile\n","    return os.path.normcase(os.path.abspath(_filename))\n","  File \"/usr/lib/python3.10/posixpath.py\", line 384, in abspath\n","    cwd = os.getcwd()\n","OSError: [Errno 107] Transport endpoint is not connected\n"]}],"source":["x1 = pickle.load(open('exp19_agrewards.pkl', 'rb'))\n","x2 = pickle.load(open('exp20_agrewards.pkl', 'rb'))\n","x3 = pickle.load(open('exp21_agrewards.pkl', 'rb'))\n","\n","plot_rewards_subplots('simple_push', 1, 1, x1, x2, x3)"]},{"cell_type":"code","execution_count":null,"metadata":{"colab":{"base_uri":"https://localhost:8080/"},"id":"Y_0ii4YxLKRw","outputId":"0d1a3883-c14b-4fcf-ca1d-98fda108c7ca"},"outputs":[{"name":"stderr","output_type":"stream","text":["ERROR:root:Internal Python error in the inspect module.\n","Below is the traceback from this internal error.\n","\n"]},{"name":"stdout","output_type":"stream","text":["Traceback (most recent call last):\n","  File \"/usr/local/lib/python3.10/dist-packages/IPython/core/interactiveshell.py\", line 3553, in run_code\n","    exec(code_obj, self.user_global_ns, self.user_ns)\n","  File \"<ipython-input-73-8834a0f32eef>\", line 1, in <cell line: 1>\n","    x1 = pickle.load(open('exp22_agrewards.pkl', 'rb'))\n","NameError: name 'pickle' is not defined\n","\n","During handling of the above exception, another exception occurred:\n","\n","Traceback (most recent call last):\n","  File \"/usr/local/lib/python3.10/dist-packages/IPython/core/interactiveshell.py\", line 2099, in showtraceback\n","    stb = value._render_traceback_()\n","AttributeError: 'NameError' object has no attribute '_render_traceback_'\n","\n","During handling of the above exception, another exception occurred:\n","\n","Traceback (most recent call last):\n","  File \"/usr/local/lib/python3.10/dist-packages/IPython/core/ultratb.py\", line 1101, in get_records\n","    return _fixed_getinnerframes(etb, number_of_lines_of_context, tb_offset)\n","  File \"/usr/local/lib/python3.10/dist-packages/IPython/core/ultratb.py\", line 248, in wrapped\n","    return f(*args, **kwargs)\n","  File \"/usr/local/lib/python3.10/dist-packages/IPython/core/ultratb.py\", line 281, in _fixed_getinnerframes\n","    records = fix_frame_records_filenames(inspect.getinnerframes(etb, context))\n","  File \"/usr/lib/python3.10/inspect.py\", line 1662, in getinnerframes\n","    frameinfo = (tb.tb_frame,) + getframeinfo(tb, context)\n","  File \"/usr/lib/python3.10/inspect.py\", line 1620, in getframeinfo\n","    filename = getsourcefile(frame) or getfile(frame)\n","  File \"/usr/lib/python3.10/inspect.py\", line 829, in getsourcefile\n","    module = getmodule(object, filename)\n","  File \"/usr/lib/python3.10/inspect.py\", line 861, in getmodule\n","    file = getabsfile(object, _filename)\n","  File \"/usr/lib/python3.10/inspect.py\", line 845, in getabsfile\n","    return os.path.normcase(os.path.abspath(_filename))\n","  File \"/usr/lib/python3.10/posixpath.py\", line 384, in abspath\n","    cwd = os.getcwd()\n","OSError: [Errno 107] Transport endpoint is not connected\n"]},{"name":"stderr","output_type":"stream","text":["ERROR:root:Internal Python error in the inspect module.\n","Below is the traceback from this internal error.\n","\n"]},{"name":"stdout","output_type":"stream","text":["Traceback (most recent call last):\n","  File \"/usr/local/lib/python3.10/dist-packages/IPython/core/interactiveshell.py\", line 3553, in run_code\n","    exec(code_obj, self.user_global_ns, self.user_ns)\n","  File \"<ipython-input-73-8834a0f32eef>\", line 1, in <cell line: 1>\n","    x1 = pickle.load(open('exp22_agrewards.pkl', 'rb'))\n","NameError: name 'pickle' is not defined\n","\n","During handling of the above exception, another exception occurred:\n","\n","Traceback (most recent call last):\n","  File \"/usr/local/lib/python3.10/dist-packages/IPython/core/interactiveshell.py\", line 2099, in showtraceback\n","    stb = value._render_traceback_()\n","AttributeError: 'NameError' object has no attribute '_render_traceback_'\n","\n","During handling of the above exception, another exception occurred:\n","\n","Traceback (most recent call last):\n","  File \"/usr/local/lib/python3.10/dist-packages/IPython/core/interactiveshell.py\", line 3473, in run_ast_nodes\n","    if (await self.run_code(code, result,  async_=asy)):\n","  File \"/usr/local/lib/python3.10/dist-packages/IPython/core/interactiveshell.py\", line 3575, in run_code\n","    self.showtraceback(running_compiled_code=True)\n","  File \"/usr/local/lib/python3.10/dist-packages/IPython/core/interactiveshell.py\", line 2101, in showtraceback\n","    stb = self.InteractiveTB.structured_traceback(etype,\n","  File \"/usr/local/lib/python3.10/dist-packages/IPython/core/ultratb.py\", line 1367, in structured_traceback\n","    return FormattedTB.structured_traceback(\n","  File \"/usr/local/lib/python3.10/dist-packages/IPython/core/ultratb.py\", line 1267, in structured_traceback\n","    return VerboseTB.structured_traceback(\n","  File \"/usr/local/lib/python3.10/dist-packages/IPython/core/ultratb.py\", line 1124, in structured_traceback\n","    formatted_exception = self.format_exception_as_a_whole(etype, evalue, etb, number_of_lines_of_context,\n","  File \"/usr/local/lib/python3.10/dist-packages/IPython/core/ultratb.py\", line 1082, in format_exception_as_a_whole\n","    last_unique, recursion_repeat = find_recursion(orig_etype, evalue, records)\n","  File \"/usr/local/lib/python3.10/dist-packages/IPython/core/ultratb.py\", line 382, in find_recursion\n","    return len(records), 0\n","TypeError: object of type 'NoneType' has no len()\n","\n","During handling of the above exception, another exception occurred:\n","\n","Traceback (most recent call last):\n","  File \"/usr/local/lib/python3.10/dist-packages/IPython/core/interactiveshell.py\", line 2099, in showtraceback\n","    stb = value._render_traceback_()\n","AttributeError: 'TypeError' object has no attribute '_render_traceback_'\n","\n","During handling of the above exception, another exception occurred:\n","\n","Traceback (most recent call last):\n","  File \"/usr/local/lib/python3.10/dist-packages/IPython/core/ultratb.py\", line 1101, in get_records\n","    return _fixed_getinnerframes(etb, number_of_lines_of_context, tb_offset)\n","  File \"/usr/local/lib/python3.10/dist-packages/IPython/core/ultratb.py\", line 248, in wrapped\n","    return f(*args, **kwargs)\n","  File \"/usr/local/lib/python3.10/dist-packages/IPython/core/ultratb.py\", line 281, in _fixed_getinnerframes\n","    records = fix_frame_records_filenames(inspect.getinnerframes(etb, context))\n","  File \"/usr/lib/python3.10/inspect.py\", line 1662, in getinnerframes\n","    frameinfo = (tb.tb_frame,) + getframeinfo(tb, context)\n","  File \"/usr/lib/python3.10/inspect.py\", line 1620, in getframeinfo\n","    filename = getsourcefile(frame) or getfile(frame)\n","  File \"/usr/lib/python3.10/inspect.py\", line 829, in getsourcefile\n","    module = getmodule(object, filename)\n","  File \"/usr/lib/python3.10/inspect.py\", line 861, in getmodule\n","    file = getabsfile(object, _filename)\n","  File \"/usr/lib/python3.10/inspect.py\", line 845, in getabsfile\n","    return os.path.normcase(os.path.abspath(_filename))\n","  File \"/usr/lib/python3.10/posixpath.py\", line 384, in abspath\n","    cwd = os.getcwd()\n","OSError: [Errno 107] Transport endpoint is not connected\n"]},{"name":"stderr","output_type":"stream","text":["ERROR:root:Internal Python error in the inspect module.\n","Below is the traceback from this internal error.\n","\n"]},{"name":"stdout","output_type":"stream","text":["Traceback (most recent call last):\n","  File \"/usr/local/lib/python3.10/dist-packages/IPython/core/interactiveshell.py\", line 3553, in run_code\n","    exec(code_obj, self.user_global_ns, self.user_ns)\n","  File \"<ipython-input-73-8834a0f32eef>\", line 1, in <cell line: 1>\n","    x1 = pickle.load(open('exp22_agrewards.pkl', 'rb'))\n","NameError: name 'pickle' is not defined\n","\n","During handling of the above exception, another exception occurred:\n","\n","Traceback (most recent call last):\n","  File \"/usr/local/lib/python3.10/dist-packages/IPython/core/interactiveshell.py\", line 2099, in showtraceback\n","    stb = value._render_traceback_()\n","AttributeError: 'NameError' object has no attribute '_render_traceback_'\n","\n","During handling of the above exception, another exception occurred:\n","\n","Traceback (most recent call last):\n","  File \"/usr/local/lib/python3.10/dist-packages/IPython/core/interactiveshell.py\", line 3473, in run_ast_nodes\n","    if (await self.run_code(code, result,  async_=asy)):\n","  File \"/usr/local/lib/python3.10/dist-packages/IPython/core/interactiveshell.py\", line 3575, in run_code\n","    self.showtraceback(running_compiled_code=True)\n","  File \"/usr/local/lib/python3.10/dist-packages/IPython/core/interactiveshell.py\", line 2101, in showtraceback\n","    stb = self.InteractiveTB.structured_traceback(etype,\n","  File \"/usr/local/lib/python3.10/dist-packages/IPython/core/ultratb.py\", line 1367, in structured_traceback\n","    return FormattedTB.structured_traceback(\n","  File \"/usr/local/lib/python3.10/dist-packages/IPython/core/ultratb.py\", line 1267, in structured_traceback\n","    return VerboseTB.structured_traceback(\n","  File \"/usr/local/lib/python3.10/dist-packages/IPython/core/ultratb.py\", line 1124, in structured_traceback\n","    formatted_exception = self.format_exception_as_a_whole(etype, evalue, etb, number_of_lines_of_context,\n","  File \"/usr/local/lib/python3.10/dist-packages/IPython/core/ultratb.py\", line 1082, in format_exception_as_a_whole\n","    last_unique, recursion_repeat = find_recursion(orig_etype, evalue, records)\n","  File \"/usr/local/lib/python3.10/dist-packages/IPython/core/ultratb.py\", line 382, in find_recursion\n","    return len(records), 0\n","TypeError: object of type 'NoneType' has no len()\n","\n","During handling of the above exception, another exception occurred:\n","\n","Traceback (most recent call last):\n","  File \"/usr/local/lib/python3.10/dist-packages/IPython/core/interactiveshell.py\", line 2099, in showtraceback\n","    stb = value._render_traceback_()\n","AttributeError: 'TypeError' object has no attribute '_render_traceback_'\n","\n","During handling of the above exception, another exception occurred:\n","\n","Traceback (most recent call last):\n","  File \"/usr/local/lib/python3.10/dist-packages/IPython/core/interactiveshell.py\", line 3030, in _run_cell\n","    return runner(coro)\n","  File \"/usr/local/lib/python3.10/dist-packages/IPython/core/async_helpers.py\", line 78, in _pseudo_sync_runner\n","    coro.send(None)\n","  File \"/usr/local/lib/python3.10/dist-packages/IPython/core/interactiveshell.py\", line 3257, in run_cell_async\n","    has_raised = await self.run_ast_nodes(code_ast.body, cell_name,\n","  File \"/usr/local/lib/python3.10/dist-packages/IPython/core/interactiveshell.py\", line 3492, in run_ast_nodes\n","    self.showtraceback()\n","  File \"/usr/local/lib/python3.10/dist-packages/IPython/core/interactiveshell.py\", line 2101, in showtraceback\n","    stb = self.InteractiveTB.structured_traceback(etype,\n","  File \"/usr/local/lib/python3.10/dist-packages/IPython/core/ultratb.py\", line 1367, in structured_traceback\n","    return FormattedTB.structured_traceback(\n","  File \"/usr/local/lib/python3.10/dist-packages/IPython/core/ultratb.py\", line 1267, in structured_traceback\n","    return VerboseTB.structured_traceback(\n","  File \"/usr/local/lib/python3.10/dist-packages/IPython/core/ultratb.py\", line 1142, in structured_traceback\n","    formatted_exceptions += self.format_exception_as_a_whole(etype, evalue, etb, lines_of_context,\n","  File \"/usr/local/lib/python3.10/dist-packages/IPython/core/ultratb.py\", line 1082, in format_exception_as_a_whole\n","    last_unique, recursion_repeat = find_recursion(orig_etype, evalue, records)\n","  File \"/usr/local/lib/python3.10/dist-packages/IPython/core/ultratb.py\", line 382, in find_recursion\n","    return len(records), 0\n","TypeError: object of type 'NoneType' has no len()\n","\n","During handling of the above exception, another exception occurred:\n","\n","Traceback (most recent call last):\n","  File \"/usr/local/lib/python3.10/dist-packages/IPython/core/interactiveshell.py\", line 2099, in showtraceback\n","    stb = value._render_traceback_()\n","AttributeError: 'TypeError' object has no attribute '_render_traceback_'\n","\n","During handling of the above exception, another exception occurred:\n","\n","Traceback (most recent call last):\n","  File \"/usr/local/lib/python3.10/dist-packages/IPython/core/ultratb.py\", line 1101, in get_records\n","    return _fixed_getinnerframes(etb, number_of_lines_of_context, tb_offset)\n","  File \"/usr/local/lib/python3.10/dist-packages/IPython/core/ultratb.py\", line 248, in wrapped\n","    return f(*args, **kwargs)\n","  File \"/usr/local/lib/python3.10/dist-packages/IPython/core/ultratb.py\", line 281, in _fixed_getinnerframes\n","    records = fix_frame_records_filenames(inspect.getinnerframes(etb, context))\n","  File \"/usr/lib/python3.10/inspect.py\", line 1662, in getinnerframes\n","    frameinfo = (tb.tb_frame,) + getframeinfo(tb, context)\n","  File \"/usr/lib/python3.10/inspect.py\", line 1620, in getframeinfo\n","    filename = getsourcefile(frame) or getfile(frame)\n","  File \"/usr/lib/python3.10/inspect.py\", line 829, in getsourcefile\n","    module = getmodule(object, filename)\n","  File \"/usr/lib/python3.10/inspect.py\", line 861, in getmodule\n","    file = getabsfile(object, _filename)\n","  File \"/usr/lib/python3.10/inspect.py\", line 845, in getabsfile\n","    return os.path.normcase(os.path.abspath(_filename))\n","  File \"/usr/lib/python3.10/posixpath.py\", line 384, in abspath\n","    cwd = os.getcwd()\n","OSError: [Errno 107] Transport endpoint is not connected\n"]}],"source":["x1 = pickle.load(open('exp22_agrewards.pkl', 'rb'))\n","x2 = pickle.load(open('exp23_agrewards.pkl', 'rb'))\n","x3 = pickle.load(open('exp24_agrewards.pkl', 'rb'))\n","\n","plot_rewards_subplots('simple_spread', 0, 3, x1, x2, x3)"]},{"cell_type":"code","execution_count":null,"metadata":{"colab":{"base_uri":"https://localhost:8080/"},"id":"WFqVR7qaLKbo","outputId":"bc5656b2-47ee-432a-d18a-14c5aefa3a4e"},"outputs":[{"name":"stderr","output_type":"stream","text":["ERROR:root:Internal Python error in the inspect module.\n","Below is the traceback from this internal error.\n","\n","ERROR:root:Internal Python error in the inspect module.\n","Below is the traceback from this internal error.\n","\n"]},{"name":"stdout","output_type":"stream","text":["Traceback (most recent call last):\n","  File \"/usr/local/lib/python3.10/dist-packages/IPython/core/interactiveshell.py\", line 3553, in run_code\n","    exec(code_obj, self.user_global_ns, self.user_ns)\n","  File \"<ipython-input-73-0d902419bd1c>\", line 1, in <cell line: 1>\n","    x1 = pickle.load(open('exp25_agrewards.pkl', 'rb'))\n","NameError: name 'pickle' is not defined\n","\n","During handling of the above exception, another exception occurred:\n","\n","Traceback (most recent call last):\n","  File \"/usr/local/lib/python3.10/dist-packages/IPython/core/interactiveshell.py\", line 2099, in showtraceback\n","    stb = value._render_traceback_()\n","AttributeError: 'NameError' object has no attribute '_render_traceback_'\n","\n","During handling of the above exception, another exception occurred:\n","\n","Traceback (most recent call last):\n","  File \"/usr/local/lib/python3.10/dist-packages/IPython/core/ultratb.py\", line 1101, in get_records\n","    return _fixed_getinnerframes(etb, number_of_lines_of_context, tb_offset)\n","  File \"/usr/local/lib/python3.10/dist-packages/IPython/core/ultratb.py\", line 248, in wrapped\n","    return f(*args, **kwargs)\n","  File \"/usr/local/lib/python3.10/dist-packages/IPython/core/ultratb.py\", line 281, in _fixed_getinnerframes\n","    records = fix_frame_records_filenames(inspect.getinnerframes(etb, context))\n","  File \"/usr/lib/python3.10/inspect.py\", line 1662, in getinnerframes\n","    frameinfo = (tb.tb_frame,) + getframeinfo(tb, context)\n","  File \"/usr/lib/python3.10/inspect.py\", line 1620, in getframeinfo\n","    filename = getsourcefile(frame) or getfile(frame)\n","  File \"/usr/lib/python3.10/inspect.py\", line 829, in getsourcefile\n","    module = getmodule(object, filename)\n","  File \"/usr/lib/python3.10/inspect.py\", line 861, in getmodule\n","    file = getabsfile(object, _filename)\n","  File \"/usr/lib/python3.10/inspect.py\", line 845, in getabsfile\n","    return os.path.normcase(os.path.abspath(_filename))\n","  File \"/usr/lib/python3.10/posixpath.py\", line 384, in abspath\n","    cwd = os.getcwd()\n","OSError: [Errno 107] Transport endpoint is not connected\n","Traceback (most recent call last):\n","  File \"/usr/local/lib/python3.10/dist-packages/IPython/core/interactiveshell.py\", line 3553, in run_code\n","    exec(code_obj, self.user_global_ns, self.user_ns)\n","  File \"<ipython-input-73-0d902419bd1c>\", line 1, in <cell line: 1>\n","    x1 = pickle.load(open('exp25_agrewards.pkl', 'rb'))\n","NameError: name 'pickle' is not defined\n","\n","During handling of the above exception, another exception occurred:\n","\n","Traceback (most recent call last):\n","  File \"/usr/local/lib/python3.10/dist-packages/IPython/core/interactiveshell.py\", line 2099, in showtraceback\n","    stb = value._render_traceback_()\n","AttributeError: 'NameError' object has no attribute '_render_traceback_'\n","\n","During handling of the above exception, another exception occurred:\n","\n","Traceback (most recent call last):\n","  File \"/usr/local/lib/python3.10/dist-packages/IPython/core/interactiveshell.py\", line 3473, in run_ast_nodes\n","    if (await self.run_code(code, result,  async_=asy)):\n","  File \"/usr/local/lib/python3.10/dist-packages/IPython/core/interactiveshell.py\", line 3575, in run_code\n","    self.showtraceback(running_compiled_code=True)\n","  File \"/usr/local/lib/python3.10/dist-packages/IPython/core/interactiveshell.py\", line 2101, in showtraceback\n","    stb = self.InteractiveTB.structured_traceback(etype,\n","  File \"/usr/local/lib/python3.10/dist-packages/IPython/core/ultratb.py\", line 1367, in structured_traceback\n","    return FormattedTB.structured_traceback(\n","  File \"/usr/local/lib/python3.10/dist-packages/IPython/core/ultratb.py\", line 1267, in structured_traceback\n","    return VerboseTB.structured_traceback(\n","  File \"/usr/local/lib/python3.10/dist-packages/IPython/core/ultratb.py\", line 1124, in structured_traceback\n","    formatted_exception = self.format_exception_as_a_whole(etype, evalue, etb, number_of_lines_of_context,\n","  File \"/usr/local/lib/python3.10/dist-packages/IPython/core/ultratb.py\", line 1082, in format_exception_as_a_whole\n","    last_unique, recursion_repeat = find_recursion(orig_etype, evalue, records)\n","  File \"/usr/local/lib/python3.10/dist-packages/IPython/core/ultratb.py\", line 382, in find_recursion\n","    return len(records), 0\n","TypeError: object of type 'NoneType' has no len()\n","\n","During handling of the above exception, another exception occurred:\n","\n","Traceback (most recent call last):\n","  File \"/usr/local/lib/python3.10/dist-packages/IPython/core/interactiveshell.py\", line 2099, in showtraceback\n","    stb = value._render_traceback_()\n","AttributeError: 'TypeError' object has no attribute '_render_traceback_'\n","\n","During handling of the above exception, another exception occurred:\n","\n","Traceback (most recent call last):\n","  File \"/usr/local/lib/python3.10/dist-packages/IPython/core/ultratb.py\", line 1101, in get_records\n","    return _fixed_getinnerframes(etb, number_of_lines_of_context, tb_offset)\n","  File \"/usr/local/lib/python3.10/dist-packages/IPython/core/ultratb.py\", line 248, in wrapped\n","    return f(*args, **kwargs)\n","  File \"/usr/local/lib/python3.10/dist-packages/IPython/core/ultratb.py\", line 281, in _fixed_getinnerframes\n","    records = fix_frame_records_filenames(inspect.getinnerframes(etb, context))\n","  File \"/usr/lib/python3.10/inspect.py\", line 1662, in getinnerframes\n","    frameinfo = (tb.tb_frame,) + getframeinfo(tb, context)\n","  File \"/usr/lib/python3.10/inspect.py\", line 1620, in getframeinfo\n","    filename = getsourcefile(frame) or getfile(frame)\n","  File \"/usr/lib/python3.10/inspect.py\", line 829, in getsourcefile\n","    module = getmodule(object, filename)\n","  File \"/usr/lib/python3.10/inspect.py\", line 861, in getmodule\n","    file = getabsfile(object, _filename)\n","  File \"/usr/lib/python3.10/inspect.py\", line 845, in getabsfile\n","    return os.path.normcase(os.path.abspath(_filename))\n","  File \"/usr/lib/python3.10/posixpath.py\", line 384, in abspath\n","    cwd = os.getcwd()\n","OSError: [Errno 107] Transport endpoint is not connected\n"]},{"name":"stderr","output_type":"stream","text":["ERROR:root:Internal Python error in the inspect module.\n","Below is the traceback from this internal error.\n","\n"]},{"name":"stdout","output_type":"stream","text":["Traceback (most recent call last):\n","  File \"/usr/local/lib/python3.10/dist-packages/IPython/core/interactiveshell.py\", line 3553, in run_code\n","    exec(code_obj, self.user_global_ns, self.user_ns)\n","  File \"<ipython-input-73-0d902419bd1c>\", line 1, in <cell line: 1>\n","    x1 = pickle.load(open('exp25_agrewards.pkl', 'rb'))\n","NameError: name 'pickle' is not defined\n","\n","During handling of the above exception, another exception occurred:\n","\n","Traceback (most recent call last):\n","  File \"/usr/local/lib/python3.10/dist-packages/IPython/core/interactiveshell.py\", line 2099, in showtraceback\n","    stb = value._render_traceback_()\n","AttributeError: 'NameError' object has no attribute '_render_traceback_'\n","\n","During handling of the above exception, another exception occurred:\n","\n","Traceback (most recent call last):\n","  File \"/usr/local/lib/python3.10/dist-packages/IPython/core/interactiveshell.py\", line 3473, in run_ast_nodes\n","    if (await self.run_code(code, result,  async_=asy)):\n","  File \"/usr/local/lib/python3.10/dist-packages/IPython/core/interactiveshell.py\", line 3575, in run_code\n","    self.showtraceback(running_compiled_code=True)\n","  File \"/usr/local/lib/python3.10/dist-packages/IPython/core/interactiveshell.py\", line 2101, in showtraceback\n","    stb = self.InteractiveTB.structured_traceback(etype,\n","  File \"/usr/local/lib/python3.10/dist-packages/IPython/core/ultratb.py\", line 1367, in structured_traceback\n","    return FormattedTB.structured_traceback(\n","  File \"/usr/local/lib/python3.10/dist-packages/IPython/core/ultratb.py\", line 1267, in structured_traceback\n","    return VerboseTB.structured_traceback(\n","  File \"/usr/local/lib/python3.10/dist-packages/IPython/core/ultratb.py\", line 1124, in structured_traceback\n","    formatted_exception = self.format_exception_as_a_whole(etype, evalue, etb, number_of_lines_of_context,\n","  File \"/usr/local/lib/python3.10/dist-packages/IPython/core/ultratb.py\", line 1082, in format_exception_as_a_whole\n","    last_unique, recursion_repeat = find_recursion(orig_etype, evalue, records)\n","  File \"/usr/local/lib/python3.10/dist-packages/IPython/core/ultratb.py\", line 382, in find_recursion\n","    return len(records), 0\n","TypeError: object of type 'NoneType' has no len()\n","\n","During handling of the above exception, another exception occurred:\n","\n","Traceback (most recent call last):\n","  File \"/usr/local/lib/python3.10/dist-packages/IPython/core/interactiveshell.py\", line 2099, in showtraceback\n","    stb = value._render_traceback_()\n","AttributeError: 'TypeError' object has no attribute '_render_traceback_'\n","\n","During handling of the above exception, another exception occurred:\n","\n","Traceback (most recent call last):\n","  File \"/usr/local/lib/python3.10/dist-packages/IPython/core/interactiveshell.py\", line 3030, in _run_cell\n","    return runner(coro)\n","  File \"/usr/local/lib/python3.10/dist-packages/IPython/core/async_helpers.py\", line 78, in _pseudo_sync_runner\n","    coro.send(None)\n","  File \"/usr/local/lib/python3.10/dist-packages/IPython/core/interactiveshell.py\", line 3257, in run_cell_async\n","    has_raised = await self.run_ast_nodes(code_ast.body, cell_name,\n","  File \"/usr/local/lib/python3.10/dist-packages/IPython/core/interactiveshell.py\", line 3492, in run_ast_nodes\n","    self.showtraceback()\n","  File \"/usr/local/lib/python3.10/dist-packages/IPython/core/interactiveshell.py\", line 2101, in showtraceback\n","    stb = self.InteractiveTB.structured_traceback(etype,\n","  File \"/usr/local/lib/python3.10/dist-packages/IPython/core/ultratb.py\", line 1367, in structured_traceback\n","    return FormattedTB.structured_traceback(\n","  File \"/usr/local/lib/python3.10/dist-packages/IPython/core/ultratb.py\", line 1267, in structured_traceback\n","    return VerboseTB.structured_traceback(\n","  File \"/usr/local/lib/python3.10/dist-packages/IPython/core/ultratb.py\", line 1142, in structured_traceback\n","    formatted_exceptions += self.format_exception_as_a_whole(etype, evalue, etb, lines_of_context,\n","  File \"/usr/local/lib/python3.10/dist-packages/IPython/core/ultratb.py\", line 1082, in format_exception_as_a_whole\n","    last_unique, recursion_repeat = find_recursion(orig_etype, evalue, records)\n","  File \"/usr/local/lib/python3.10/dist-packages/IPython/core/ultratb.py\", line 382, in find_recursion\n","    return len(records), 0\n","TypeError: object of type 'NoneType' has no len()\n","\n","During handling of the above exception, another exception occurred:\n","\n","Traceback (most recent call last):\n","  File \"/usr/local/lib/python3.10/dist-packages/IPython/core/interactiveshell.py\", line 2099, in showtraceback\n","    stb = value._render_traceback_()\n","AttributeError: 'TypeError' object has no attribute '_render_traceback_'\n","\n","During handling of the above exception, another exception occurred:\n","\n","Traceback (most recent call last):\n","  File \"/usr/local/lib/python3.10/dist-packages/IPython/core/ultratb.py\", line 1101, in get_records\n","    return _fixed_getinnerframes(etb, number_of_lines_of_context, tb_offset)\n","  File \"/usr/local/lib/python3.10/dist-packages/IPython/core/ultratb.py\", line 248, in wrapped\n","    return f(*args, **kwargs)\n","  File \"/usr/local/lib/python3.10/dist-packages/IPython/core/ultratb.py\", line 281, in _fixed_getinnerframes\n","    records = fix_frame_records_filenames(inspect.getinnerframes(etb, context))\n","  File \"/usr/lib/python3.10/inspect.py\", line 1662, in getinnerframes\n","    frameinfo = (tb.tb_frame,) + getframeinfo(tb, context)\n","  File \"/usr/lib/python3.10/inspect.py\", line 1620, in getframeinfo\n","    filename = getsourcefile(frame) or getfile(frame)\n","  File \"/usr/lib/python3.10/inspect.py\", line 829, in getsourcefile\n","    module = getmodule(object, filename)\n","  File \"/usr/lib/python3.10/inspect.py\", line 861, in getmodule\n","    file = getabsfile(object, _filename)\n","  File \"/usr/lib/python3.10/inspect.py\", line 845, in getabsfile\n","    return os.path.normcase(os.path.abspath(_filename))\n","  File \"/usr/lib/python3.10/posixpath.py\", line 384, in abspath\n","    cwd = os.getcwd()\n","OSError: [Errno 107] Transport endpoint is not connected\n"]}],"source":["x1 = pickle.load(open('exp25_agrewards.pkl', 'rb'))\n","x2 = pickle.load(open('exp26_agrewards.pkl', 'rb'))\n","x3 = pickle.load(open('exp27_agrewards.pkl', 'rb'))\n","\n","plot_rewards_subplots('simple_reference', 0, 2, x1, x2, x3)"]},{"cell_type":"code","execution_count":null,"metadata":{"colab":{"base_uri":"https://localhost:8080/"},"id":"5StkPobALNjH","outputId":"aec67c44-58ba-4924-d7b2-f48356627f6f"},"outputs":[{"name":"stderr","output_type":"stream","text":["ERROR:root:Internal Python error in the inspect module.\n","Below is the traceback from this internal error.\n","\n","ERROR:root:Internal Python error in the inspect module.\n","Below is the traceback from this internal error.\n","\n"]},{"name":"stdout","output_type":"stream","text":["Traceback (most recent call last):\n","  File \"/usr/local/lib/python3.10/dist-packages/IPython/core/interactiveshell.py\", line 3553, in run_code\n","    exec(code_obj, self.user_global_ns, self.user_ns)\n","  File \"<ipython-input-73-5c301b3c2a4b>\", line 1, in <cell line: 1>\n","    x1 = pickle.load(open('exp28_agrewards.pkl', 'rb'))\n","NameError: name 'pickle' is not defined\n","\n","During handling of the above exception, another exception occurred:\n","\n","Traceback (most recent call last):\n","  File \"/usr/local/lib/python3.10/dist-packages/IPython/core/interactiveshell.py\", line 2099, in showtraceback\n","    stb = value._render_traceback_()\n","AttributeError: 'NameError' object has no attribute '_render_traceback_'\n","\n","During handling of the above exception, another exception occurred:\n","\n","Traceback (most recent call last):\n","  File \"/usr/local/lib/python3.10/dist-packages/IPython/core/ultratb.py\", line 1101, in get_records\n","    return _fixed_getinnerframes(etb, number_of_lines_of_context, tb_offset)\n","  File \"/usr/local/lib/python3.10/dist-packages/IPython/core/ultratb.py\", line 248, in wrapped\n","    return f(*args, **kwargs)\n","  File \"/usr/local/lib/python3.10/dist-packages/IPython/core/ultratb.py\", line 281, in _fixed_getinnerframes\n","    records = fix_frame_records_filenames(inspect.getinnerframes(etb, context))\n","  File \"/usr/lib/python3.10/inspect.py\", line 1662, in getinnerframes\n","    frameinfo = (tb.tb_frame,) + getframeinfo(tb, context)\n","  File \"/usr/lib/python3.10/inspect.py\", line 1620, in getframeinfo\n","    filename = getsourcefile(frame) or getfile(frame)\n","  File \"/usr/lib/python3.10/inspect.py\", line 829, in getsourcefile\n","    module = getmodule(object, filename)\n","  File \"/usr/lib/python3.10/inspect.py\", line 861, in getmodule\n","    file = getabsfile(object, _filename)\n","  File \"/usr/lib/python3.10/inspect.py\", line 845, in getabsfile\n","    return os.path.normcase(os.path.abspath(_filename))\n","  File \"/usr/lib/python3.10/posixpath.py\", line 384, in abspath\n","    cwd = os.getcwd()\n","OSError: [Errno 107] Transport endpoint is not connected\n","Traceback (most recent call last):\n","  File \"/usr/local/lib/python3.10/dist-packages/IPython/core/interactiveshell.py\", line 3553, in run_code\n","    exec(code_obj, self.user_global_ns, self.user_ns)\n","  File \"<ipython-input-73-5c301b3c2a4b>\", line 1, in <cell line: 1>\n","    x1 = pickle.load(open('exp28_agrewards.pkl', 'rb'))\n","NameError: name 'pickle' is not defined\n","\n","During handling of the above exception, another exception occurred:\n","\n","Traceback (most recent call last):\n","  File \"/usr/local/lib/python3.10/dist-packages/IPython/core/interactiveshell.py\", line 2099, in showtraceback\n","    stb = value._render_traceback_()\n","AttributeError: 'NameError' object has no attribute '_render_traceback_'\n","\n","During handling of the above exception, another exception occurred:\n","\n","Traceback (most recent call last):\n","  File \"/usr/local/lib/python3.10/dist-packages/IPython/core/interactiveshell.py\", line 3473, in run_ast_nodes\n","    if (await self.run_code(code, result,  async_=asy)):\n","  File \"/usr/local/lib/python3.10/dist-packages/IPython/core/interactiveshell.py\", line 3575, in run_code\n","    self.showtraceback(running_compiled_code=True)\n","  File \"/usr/local/lib/python3.10/dist-packages/IPython/core/interactiveshell.py\", line 2101, in showtraceback\n","    stb = self.InteractiveTB.structured_traceback(etype,\n","  File \"/usr/local/lib/python3.10/dist-packages/IPython/core/ultratb.py\", line 1367, in structured_traceback\n","    return FormattedTB.structured_traceback(\n","  File \"/usr/local/lib/python3.10/dist-packages/IPython/core/ultratb.py\", line 1267, in structured_traceback\n","    return VerboseTB.structured_traceback(\n","  File \"/usr/local/lib/python3.10/dist-packages/IPython/core/ultratb.py\", line 1124, in structured_traceback\n","    formatted_exception = self.format_exception_as_a_whole(etype, evalue, etb, number_of_lines_of_context,\n","  File \"/usr/local/lib/python3.10/dist-packages/IPython/core/ultratb.py\", line 1082, in format_exception_as_a_whole\n","    last_unique, recursion_repeat = find_recursion(orig_etype, evalue, records)\n","  File \"/usr/local/lib/python3.10/dist-packages/IPython/core/ultratb.py\", line 382, in find_recursion\n","    return len(records), 0\n","TypeError: object of type 'NoneType' has no len()\n","\n","During handling of the above exception, another exception occurred:\n","\n","Traceback (most recent call last):\n","  File \"/usr/local/lib/python3.10/dist-packages/IPython/core/interactiveshell.py\", line 2099, in showtraceback\n","    stb = value._render_traceback_()\n","AttributeError: 'TypeError' object has no attribute '_render_traceback_'\n","\n","During handling of the above exception, another exception occurred:\n","\n","Traceback (most recent call last):\n","  File \"/usr/local/lib/python3.10/dist-packages/IPython/core/ultratb.py\", line 1101, in get_records\n","    return _fixed_getinnerframes(etb, number_of_lines_of_context, tb_offset)\n","  File \"/usr/local/lib/python3.10/dist-packages/IPython/core/ultratb.py\", line 248, in wrapped\n","    return f(*args, **kwargs)\n","  File \"/usr/local/lib/python3.10/dist-packages/IPython/core/ultratb.py\", line 281, in _fixed_getinnerframes\n","    records = fix_frame_records_filenames(inspect.getinnerframes(etb, context))\n","  File \"/usr/lib/python3.10/inspect.py\", line 1662, in getinnerframes\n","    frameinfo = (tb.tb_frame,) + getframeinfo(tb, context)\n","  File \"/usr/lib/python3.10/inspect.py\", line 1620, in getframeinfo\n","    filename = getsourcefile(frame) or getfile(frame)\n","  File \"/usr/lib/python3.10/inspect.py\", line 829, in getsourcefile\n","    module = getmodule(object, filename)\n","  File \"/usr/lib/python3.10/inspect.py\", line 861, in getmodule\n","    file = getabsfile(object, _filename)\n","  File \"/usr/lib/python3.10/inspect.py\", line 845, in getabsfile\n","    return os.path.normcase(os.path.abspath(_filename))\n","  File \"/usr/lib/python3.10/posixpath.py\", line 384, in abspath\n","    cwd = os.getcwd()\n","OSError: [Errno 107] Transport endpoint is not connected\n"]},{"name":"stderr","output_type":"stream","text":["ERROR:root:Internal Python error in the inspect module.\n","Below is the traceback from this internal error.\n","\n"]},{"name":"stdout","output_type":"stream","text":["Traceback (most recent call last):\n","  File \"/usr/local/lib/python3.10/dist-packages/IPython/core/interactiveshell.py\", line 3553, in run_code\n","    exec(code_obj, self.user_global_ns, self.user_ns)\n","  File \"<ipython-input-73-5c301b3c2a4b>\", line 1, in <cell line: 1>\n","    x1 = pickle.load(open('exp28_agrewards.pkl', 'rb'))\n","NameError: name 'pickle' is not defined\n","\n","During handling of the above exception, another exception occurred:\n","\n","Traceback (most recent call last):\n","  File \"/usr/local/lib/python3.10/dist-packages/IPython/core/interactiveshell.py\", line 2099, in showtraceback\n","    stb = value._render_traceback_()\n","AttributeError: 'NameError' object has no attribute '_render_traceback_'\n","\n","During handling of the above exception, another exception occurred:\n","\n","Traceback (most recent call last):\n","  File \"/usr/local/lib/python3.10/dist-packages/IPython/core/interactiveshell.py\", line 3473, in run_ast_nodes\n","    if (await self.run_code(code, result,  async_=asy)):\n","  File \"/usr/local/lib/python3.10/dist-packages/IPython/core/interactiveshell.py\", line 3575, in run_code\n","    self.showtraceback(running_compiled_code=True)\n","  File \"/usr/local/lib/python3.10/dist-packages/IPython/core/interactiveshell.py\", line 2101, in showtraceback\n","    stb = self.InteractiveTB.structured_traceback(etype,\n","  File \"/usr/local/lib/python3.10/dist-packages/IPython/core/ultratb.py\", line 1367, in structured_traceback\n","    return FormattedTB.structured_traceback(\n","  File \"/usr/local/lib/python3.10/dist-packages/IPython/core/ultratb.py\", line 1267, in structured_traceback\n","    return VerboseTB.structured_traceback(\n","  File \"/usr/local/lib/python3.10/dist-packages/IPython/core/ultratb.py\", line 1124, in structured_traceback\n","    formatted_exception = self.format_exception_as_a_whole(etype, evalue, etb, number_of_lines_of_context,\n","  File \"/usr/local/lib/python3.10/dist-packages/IPython/core/ultratb.py\", line 1082, in format_exception_as_a_whole\n","    last_unique, recursion_repeat = find_recursion(orig_etype, evalue, records)\n","  File \"/usr/local/lib/python3.10/dist-packages/IPython/core/ultratb.py\", line 382, in find_recursion\n","    return len(records), 0\n","TypeError: object of type 'NoneType' has no len()\n","\n","During handling of the above exception, another exception occurred:\n","\n","Traceback (most recent call last):\n","  File \"/usr/local/lib/python3.10/dist-packages/IPython/core/interactiveshell.py\", line 2099, in showtraceback\n","    stb = value._render_traceback_()\n","AttributeError: 'TypeError' object has no attribute '_render_traceback_'\n","\n","During handling of the above exception, another exception occurred:\n","\n","Traceback (most recent call last):\n","  File \"/usr/local/lib/python3.10/dist-packages/IPython/core/interactiveshell.py\", line 3030, in _run_cell\n","    return runner(coro)\n","  File \"/usr/local/lib/python3.10/dist-packages/IPython/core/async_helpers.py\", line 78, in _pseudo_sync_runner\n","    coro.send(None)\n","  File \"/usr/local/lib/python3.10/dist-packages/IPython/core/interactiveshell.py\", line 3257, in run_cell_async\n","    has_raised = await self.run_ast_nodes(code_ast.body, cell_name,\n","  File \"/usr/local/lib/python3.10/dist-packages/IPython/core/interactiveshell.py\", line 3492, in run_ast_nodes\n","    self.showtraceback()\n","  File \"/usr/local/lib/python3.10/dist-packages/IPython/core/interactiveshell.py\", line 2101, in showtraceback\n","    stb = self.InteractiveTB.structured_traceback(etype,\n","  File \"/usr/local/lib/python3.10/dist-packages/IPython/core/ultratb.py\", line 1367, in structured_traceback\n","    return FormattedTB.structured_traceback(\n","  File \"/usr/local/lib/python3.10/dist-packages/IPython/core/ultratb.py\", line 1267, in structured_traceback\n","    return VerboseTB.structured_traceback(\n","  File \"/usr/local/lib/python3.10/dist-packages/IPython/core/ultratb.py\", line 1142, in structured_traceback\n","    formatted_exceptions += self.format_exception_as_a_whole(etype, evalue, etb, lines_of_context,\n","  File \"/usr/local/lib/python3.10/dist-packages/IPython/core/ultratb.py\", line 1082, in format_exception_as_a_whole\n","    last_unique, recursion_repeat = find_recursion(orig_etype, evalue, records)\n","  File \"/usr/local/lib/python3.10/dist-packages/IPython/core/ultratb.py\", line 382, in find_recursion\n","    return len(records), 0\n","TypeError: object of type 'NoneType' has no len()\n","\n","During handling of the above exception, another exception occurred:\n","\n","Traceback (most recent call last):\n","  File \"/usr/local/lib/python3.10/dist-packages/IPython/core/interactiveshell.py\", line 2099, in showtraceback\n","    stb = value._render_traceback_()\n","AttributeError: 'TypeError' object has no attribute '_render_traceback_'\n","\n","During handling of the above exception, another exception occurred:\n","\n","Traceback (most recent call last):\n","  File \"/usr/local/lib/python3.10/dist-packages/IPython/core/ultratb.py\", line 1101, in get_records\n","    return _fixed_getinnerframes(etb, number_of_lines_of_context, tb_offset)\n","  File \"/usr/local/lib/python3.10/dist-packages/IPython/core/ultratb.py\", line 248, in wrapped\n","    return f(*args, **kwargs)\n","  File \"/usr/local/lib/python3.10/dist-packages/IPython/core/ultratb.py\", line 281, in _fixed_getinnerframes\n","    records = fix_frame_records_filenames(inspect.getinnerframes(etb, context))\n","  File \"/usr/lib/python3.10/inspect.py\", line 1662, in getinnerframes\n","    frameinfo = (tb.tb_frame,) + getframeinfo(tb, context)\n","  File \"/usr/lib/python3.10/inspect.py\", line 1620, in getframeinfo\n","    filename = getsourcefile(frame) or getfile(frame)\n","  File \"/usr/lib/python3.10/inspect.py\", line 829, in getsourcefile\n","    module = getmodule(object, filename)\n","  File \"/usr/lib/python3.10/inspect.py\", line 861, in getmodule\n","    file = getabsfile(object, _filename)\n","  File \"/usr/lib/python3.10/inspect.py\", line 845, in getabsfile\n","    return os.path.normcase(os.path.abspath(_filename))\n","  File \"/usr/lib/python3.10/posixpath.py\", line 384, in abspath\n","    cwd = os.getcwd()\n","OSError: [Errno 107] Transport endpoint is not connected\n"]}],"source":["x1 = pickle.load(open('exp28_agrewards.pkl', 'rb'))\n","x2 = pickle.load(open('exp29_agrewards.pkl', 'rb'))\n","x3 = pickle.load(open('exp30_agrewards.pkl', 'rb'))\n","\n","plot_rewards_subplots('simple_tag', 3, 1, x1, x2, x3)"]},{"cell_type":"code","execution_count":null,"metadata":{"colab":{"base_uri":"https://localhost:8080/"},"id":"TRKH_PEiLNuV","outputId":"daac4f26-7d7c-439c-da4f-cacbca4b991b"},"outputs":[{"name":"stderr","output_type":"stream","text":["ERROR:root:Internal Python error in the inspect module.\n","Below is the traceback from this internal error.\n","\n","ERROR:root:Internal Python error in the inspect module.\n","Below is the traceback from this internal error.\n","\n"]},{"name":"stdout","output_type":"stream","text":["Traceback (most recent call last):\n","  File \"/usr/local/lib/python3.10/dist-packages/IPython/core/interactiveshell.py\", line 3553, in run_code\n","    exec(code_obj, self.user_global_ns, self.user_ns)\n","  File \"<ipython-input-73-10d214bb6c8f>\", line 1, in <cell line: 1>\n","    x1 = pickle.load(open('exp31_agrewards.pkl', 'rb'))\n","NameError: name 'pickle' is not defined\n","\n","During handling of the above exception, another exception occurred:\n","\n","Traceback (most recent call last):\n","  File \"/usr/local/lib/python3.10/dist-packages/IPython/core/interactiveshell.py\", line 2099, in showtraceback\n","    stb = value._render_traceback_()\n","AttributeError: 'NameError' object has no attribute '_render_traceback_'\n","\n","During handling of the above exception, another exception occurred:\n","\n","Traceback (most recent call last):\n","  File \"/usr/local/lib/python3.10/dist-packages/IPython/core/ultratb.py\", line 1101, in get_records\n","    return _fixed_getinnerframes(etb, number_of_lines_of_context, tb_offset)\n","  File \"/usr/local/lib/python3.10/dist-packages/IPython/core/ultratb.py\", line 248, in wrapped\n","    return f(*args, **kwargs)\n","  File \"/usr/local/lib/python3.10/dist-packages/IPython/core/ultratb.py\", line 281, in _fixed_getinnerframes\n","    records = fix_frame_records_filenames(inspect.getinnerframes(etb, context))\n","  File \"/usr/lib/python3.10/inspect.py\", line 1662, in getinnerframes\n","    frameinfo = (tb.tb_frame,) + getframeinfo(tb, context)\n","  File \"/usr/lib/python3.10/inspect.py\", line 1620, in getframeinfo\n","    filename = getsourcefile(frame) or getfile(frame)\n","  File \"/usr/lib/python3.10/inspect.py\", line 829, in getsourcefile\n","    module = getmodule(object, filename)\n","  File \"/usr/lib/python3.10/inspect.py\", line 861, in getmodule\n","    file = getabsfile(object, _filename)\n","  File \"/usr/lib/python3.10/inspect.py\", line 845, in getabsfile\n","    return os.path.normcase(os.path.abspath(_filename))\n","  File \"/usr/lib/python3.10/posixpath.py\", line 384, in abspath\n","    cwd = os.getcwd()\n","OSError: [Errno 107] Transport endpoint is not connected\n","Traceback (most recent call last):\n","  File \"/usr/local/lib/python3.10/dist-packages/IPython/core/interactiveshell.py\", line 3553, in run_code\n","    exec(code_obj, self.user_global_ns, self.user_ns)\n","  File \"<ipython-input-73-10d214bb6c8f>\", line 1, in <cell line: 1>\n","    x1 = pickle.load(open('exp31_agrewards.pkl', 'rb'))\n","NameError: name 'pickle' is not defined\n","\n","During handling of the above exception, another exception occurred:\n","\n","Traceback (most recent call last):\n","  File \"/usr/local/lib/python3.10/dist-packages/IPython/core/interactiveshell.py\", line 2099, in showtraceback\n","    stb = value._render_traceback_()\n","AttributeError: 'NameError' object has no attribute '_render_traceback_'\n","\n","During handling of the above exception, another exception occurred:\n","\n","Traceback (most recent call last):\n","  File \"/usr/local/lib/python3.10/dist-packages/IPython/core/interactiveshell.py\", line 3473, in run_ast_nodes\n","    if (await self.run_code(code, result,  async_=asy)):\n","  File \"/usr/local/lib/python3.10/dist-packages/IPython/core/interactiveshell.py\", line 3575, in run_code\n","    self.showtraceback(running_compiled_code=True)\n","  File \"/usr/local/lib/python3.10/dist-packages/IPython/core/interactiveshell.py\", line 2101, in showtraceback\n","    stb = self.InteractiveTB.structured_traceback(etype,\n","  File \"/usr/local/lib/python3.10/dist-packages/IPython/core/ultratb.py\", line 1367, in structured_traceback\n","    return FormattedTB.structured_traceback(\n","  File \"/usr/local/lib/python3.10/dist-packages/IPython/core/ultratb.py\", line 1267, in structured_traceback\n","    return VerboseTB.structured_traceback(\n","  File \"/usr/local/lib/python3.10/dist-packages/IPython/core/ultratb.py\", line 1124, in structured_traceback\n","    formatted_exception = self.format_exception_as_a_whole(etype, evalue, etb, number_of_lines_of_context,\n","  File \"/usr/local/lib/python3.10/dist-packages/IPython/core/ultratb.py\", line 1082, in format_exception_as_a_whole\n","    last_unique, recursion_repeat = find_recursion(orig_etype, evalue, records)\n","  File \"/usr/local/lib/python3.10/dist-packages/IPython/core/ultratb.py\", line 382, in find_recursion\n","    return len(records), 0\n","TypeError: object of type 'NoneType' has no len()\n","\n","During handling of the above exception, another exception occurred:\n","\n","Traceback (most recent call last):\n","  File \"/usr/local/lib/python3.10/dist-packages/IPython/core/interactiveshell.py\", line 2099, in showtraceback\n","    stb = value._render_traceback_()\n","AttributeError: 'TypeError' object has no attribute '_render_traceback_'\n","\n","During handling of the above exception, another exception occurred:\n","\n","Traceback (most recent call last):\n","  File \"/usr/local/lib/python3.10/dist-packages/IPython/core/ultratb.py\", line 1101, in get_records\n","    return _fixed_getinnerframes(etb, number_of_lines_of_context, tb_offset)\n","  File \"/usr/local/lib/python3.10/dist-packages/IPython/core/ultratb.py\", line 248, in wrapped\n","    return f(*args, **kwargs)\n","  File \"/usr/local/lib/python3.10/dist-packages/IPython/core/ultratb.py\", line 281, in _fixed_getinnerframes\n","    records = fix_frame_records_filenames(inspect.getinnerframes(etb, context))\n","  File \"/usr/lib/python3.10/inspect.py\", line 1662, in getinnerframes\n","    frameinfo = (tb.tb_frame,) + getframeinfo(tb, context)\n","  File \"/usr/lib/python3.10/inspect.py\", line 1620, in getframeinfo\n","    filename = getsourcefile(frame) or getfile(frame)\n","  File \"/usr/lib/python3.10/inspect.py\", line 829, in getsourcefile\n","    module = getmodule(object, filename)\n","  File \"/usr/lib/python3.10/inspect.py\", line 861, in getmodule\n","    file = getabsfile(object, _filename)\n","  File \"/usr/lib/python3.10/inspect.py\", line 845, in getabsfile\n","    return os.path.normcase(os.path.abspath(_filename))\n","  File \"/usr/lib/python3.10/posixpath.py\", line 384, in abspath\n","    cwd = os.getcwd()\n","OSError: [Errno 107] Transport endpoint is not connected\n"]},{"name":"stderr","output_type":"stream","text":["ERROR:root:Internal Python error in the inspect module.\n","Below is the traceback from this internal error.\n","\n"]},{"name":"stdout","output_type":"stream","text":["Traceback (most recent call last):\n","  File \"/usr/local/lib/python3.10/dist-packages/IPython/core/interactiveshell.py\", line 3553, in run_code\n","    exec(code_obj, self.user_global_ns, self.user_ns)\n","  File \"<ipython-input-73-10d214bb6c8f>\", line 1, in <cell line: 1>\n","    x1 = pickle.load(open('exp31_agrewards.pkl', 'rb'))\n","NameError: name 'pickle' is not defined\n","\n","During handling of the above exception, another exception occurred:\n","\n","Traceback (most recent call last):\n","  File \"/usr/local/lib/python3.10/dist-packages/IPython/core/interactiveshell.py\", line 2099, in showtraceback\n","    stb = value._render_traceback_()\n","AttributeError: 'NameError' object has no attribute '_render_traceback_'\n","\n","During handling of the above exception, another exception occurred:\n","\n","Traceback (most recent call last):\n","  File \"/usr/local/lib/python3.10/dist-packages/IPython/core/interactiveshell.py\", line 3473, in run_ast_nodes\n","    if (await self.run_code(code, result,  async_=asy)):\n","  File \"/usr/local/lib/python3.10/dist-packages/IPython/core/interactiveshell.py\", line 3575, in run_code\n","    self.showtraceback(running_compiled_code=True)\n","  File \"/usr/local/lib/python3.10/dist-packages/IPython/core/interactiveshell.py\", line 2101, in showtraceback\n","    stb = self.InteractiveTB.structured_traceback(etype,\n","  File \"/usr/local/lib/python3.10/dist-packages/IPython/core/ultratb.py\", line 1367, in structured_traceback\n","    return FormattedTB.structured_traceback(\n","  File \"/usr/local/lib/python3.10/dist-packages/IPython/core/ultratb.py\", line 1267, in structured_traceback\n","    return VerboseTB.structured_traceback(\n","  File \"/usr/local/lib/python3.10/dist-packages/IPython/core/ultratb.py\", line 1124, in structured_traceback\n","    formatted_exception = self.format_exception_as_a_whole(etype, evalue, etb, number_of_lines_of_context,\n","  File \"/usr/local/lib/python3.10/dist-packages/IPython/core/ultratb.py\", line 1082, in format_exception_as_a_whole\n","    last_unique, recursion_repeat = find_recursion(orig_etype, evalue, records)\n","  File \"/usr/local/lib/python3.10/dist-packages/IPython/core/ultratb.py\", line 382, in find_recursion\n","    return len(records), 0\n","TypeError: object of type 'NoneType' has no len()\n","\n","During handling of the above exception, another exception occurred:\n","\n","Traceback (most recent call last):\n","  File \"/usr/local/lib/python3.10/dist-packages/IPython/core/interactiveshell.py\", line 2099, in showtraceback\n","    stb = value._render_traceback_()\n","AttributeError: 'TypeError' object has no attribute '_render_traceback_'\n","\n","During handling of the above exception, another exception occurred:\n","\n","Traceback (most recent call last):\n","  File \"/usr/local/lib/python3.10/dist-packages/IPython/core/interactiveshell.py\", line 3030, in _run_cell\n","    return runner(coro)\n","  File \"/usr/local/lib/python3.10/dist-packages/IPython/core/async_helpers.py\", line 78, in _pseudo_sync_runner\n","    coro.send(None)\n","  File \"/usr/local/lib/python3.10/dist-packages/IPython/core/interactiveshell.py\", line 3257, in run_cell_async\n","    has_raised = await self.run_ast_nodes(code_ast.body, cell_name,\n","  File \"/usr/local/lib/python3.10/dist-packages/IPython/core/interactiveshell.py\", line 3492, in run_ast_nodes\n","    self.showtraceback()\n","  File \"/usr/local/lib/python3.10/dist-packages/IPython/core/interactiveshell.py\", line 2101, in showtraceback\n","    stb = self.InteractiveTB.structured_traceback(etype,\n","  File \"/usr/local/lib/python3.10/dist-packages/IPython/core/ultratb.py\", line 1367, in structured_traceback\n","    return FormattedTB.structured_traceback(\n","  File \"/usr/local/lib/python3.10/dist-packages/IPython/core/ultratb.py\", line 1267, in structured_traceback\n","    return VerboseTB.structured_traceback(\n","  File \"/usr/local/lib/python3.10/dist-packages/IPython/core/ultratb.py\", line 1142, in structured_traceback\n","    formatted_exceptions += self.format_exception_as_a_whole(etype, evalue, etb, lines_of_context,\n","  File \"/usr/local/lib/python3.10/dist-packages/IPython/core/ultratb.py\", line 1082, in format_exception_as_a_whole\n","    last_unique, recursion_repeat = find_recursion(orig_etype, evalue, records)\n","  File \"/usr/local/lib/python3.10/dist-packages/IPython/core/ultratb.py\", line 382, in find_recursion\n","    return len(records), 0\n","TypeError: object of type 'NoneType' has no len()\n","\n","During handling of the above exception, another exception occurred:\n","\n","Traceback (most recent call last):\n","  File \"/usr/local/lib/python3.10/dist-packages/IPython/core/interactiveshell.py\", line 2099, in showtraceback\n","    stb = value._render_traceback_()\n","AttributeError: 'TypeError' object has no attribute '_render_traceback_'\n","\n","During handling of the above exception, another exception occurred:\n","\n","Traceback (most recent call last):\n","  File \"/usr/local/lib/python3.10/dist-packages/IPython/core/ultratb.py\", line 1101, in get_records\n","    return _fixed_getinnerframes(etb, number_of_lines_of_context, tb_offset)\n","  File \"/usr/local/lib/python3.10/dist-packages/IPython/core/ultratb.py\", line 248, in wrapped\n","    return f(*args, **kwargs)\n","  File \"/usr/local/lib/python3.10/dist-packages/IPython/core/ultratb.py\", line 281, in _fixed_getinnerframes\n","    records = fix_frame_records_filenames(inspect.getinnerframes(etb, context))\n","  File \"/usr/lib/python3.10/inspect.py\", line 1662, in getinnerframes\n","    frameinfo = (tb.tb_frame,) + getframeinfo(tb, context)\n","  File \"/usr/lib/python3.10/inspect.py\", line 1620, in getframeinfo\n","    filename = getsourcefile(frame) or getfile(frame)\n","  File \"/usr/lib/python3.10/inspect.py\", line 829, in getsourcefile\n","    module = getmodule(object, filename)\n","  File \"/usr/lib/python3.10/inspect.py\", line 861, in getmodule\n","    file = getabsfile(object, _filename)\n","  File \"/usr/lib/python3.10/inspect.py\", line 845, in getabsfile\n","    return os.path.normcase(os.path.abspath(_filename))\n","  File \"/usr/lib/python3.10/posixpath.py\", line 384, in abspath\n","    cwd = os.getcwd()\n","OSError: [Errno 107] Transport endpoint is not connected\n"]}],"source":["x1 = pickle.load(open('exp31_agrewards.pkl', 'rb'))\n","x2 = pickle.load(open('exp32_agrewards.pkl', 'rb'))\n","x3 = pickle.load(open('exp33_agrewards.pkl', 'rb'))\n","\n","plot_rewards_subplots('simple_world_comm', 3, 2, x1, x2, x3)"]},{"cell_type":"code","execution_count":null,"metadata":{"colab":{"base_uri":"https://localhost:8080/"},"id":"Mb4LC3QpLN5d","outputId":"36c07e2e-ac2f-456b-c77d-f9c94a9aadfe"},"outputs":[{"name":"stderr","output_type":"stream","text":["ERROR:root:Internal Python error in the inspect module.\n","Below is the traceback from this internal error.\n","\n","ERROR:root:Internal Python error in the inspect module.\n","Below is the traceback from this internal error.\n","\n"]},{"name":"stdout","output_type":"stream","text":["Traceback (most recent call last):\n","  File \"/usr/local/lib/python3.10/dist-packages/IPython/core/interactiveshell.py\", line 3553, in run_code\n","    exec(code_obj, self.user_global_ns, self.user_ns)\n","  File \"<ipython-input-73-d6d497bff8bf>\", line 1, in <cell line: 1>\n","    x1 = pickle.load(open('exp34_agrewards.pkl', 'rb'))\n","NameError: name 'pickle' is not defined\n","\n","During handling of the above exception, another exception occurred:\n","\n","Traceback (most recent call last):\n","  File \"/usr/local/lib/python3.10/dist-packages/IPython/core/interactiveshell.py\", line 2099, in showtraceback\n","    stb = value._render_traceback_()\n","AttributeError: 'NameError' object has no attribute '_render_traceback_'\n","\n","During handling of the above exception, another exception occurred:\n","\n","Traceback (most recent call last):\n","  File \"/usr/local/lib/python3.10/dist-packages/IPython/core/ultratb.py\", line 1101, in get_records\n","    return _fixed_getinnerframes(etb, number_of_lines_of_context, tb_offset)\n","  File \"/usr/local/lib/python3.10/dist-packages/IPython/core/ultratb.py\", line 248, in wrapped\n","    return f(*args, **kwargs)\n","  File \"/usr/local/lib/python3.10/dist-packages/IPython/core/ultratb.py\", line 281, in _fixed_getinnerframes\n","    records = fix_frame_records_filenames(inspect.getinnerframes(etb, context))\n","  File \"/usr/lib/python3.10/inspect.py\", line 1662, in getinnerframes\n","    frameinfo = (tb.tb_frame,) + getframeinfo(tb, context)\n","  File \"/usr/lib/python3.10/inspect.py\", line 1620, in getframeinfo\n","    filename = getsourcefile(frame) or getfile(frame)\n","  File \"/usr/lib/python3.10/inspect.py\", line 829, in getsourcefile\n","    module = getmodule(object, filename)\n","  File \"/usr/lib/python3.10/inspect.py\", line 861, in getmodule\n","    file = getabsfile(object, _filename)\n","  File \"/usr/lib/python3.10/inspect.py\", line 845, in getabsfile\n","    return os.path.normcase(os.path.abspath(_filename))\n","  File \"/usr/lib/python3.10/posixpath.py\", line 384, in abspath\n","    cwd = os.getcwd()\n","OSError: [Errno 107] Transport endpoint is not connected\n","Traceback (most recent call last):\n","  File \"/usr/local/lib/python3.10/dist-packages/IPython/core/interactiveshell.py\", line 3553, in run_code\n","    exec(code_obj, self.user_global_ns, self.user_ns)\n","  File \"<ipython-input-73-d6d497bff8bf>\", line 1, in <cell line: 1>\n","    x1 = pickle.load(open('exp34_agrewards.pkl', 'rb'))\n","NameError: name 'pickle' is not defined\n","\n","During handling of the above exception, another exception occurred:\n","\n","Traceback (most recent call last):\n","  File \"/usr/local/lib/python3.10/dist-packages/IPython/core/interactiveshell.py\", line 2099, in showtraceback\n","    stb = value._render_traceback_()\n","AttributeError: 'NameError' object has no attribute '_render_traceback_'\n","\n","During handling of the above exception, another exception occurred:\n","\n","Traceback (most recent call last):\n","  File \"/usr/local/lib/python3.10/dist-packages/IPython/core/interactiveshell.py\", line 3473, in run_ast_nodes\n","    if (await self.run_code(code, result,  async_=asy)):\n","  File \"/usr/local/lib/python3.10/dist-packages/IPython/core/interactiveshell.py\", line 3575, in run_code\n","    self.showtraceback(running_compiled_code=True)\n","  File \"/usr/local/lib/python3.10/dist-packages/IPython/core/interactiveshell.py\", line 2101, in showtraceback\n","    stb = self.InteractiveTB.structured_traceback(etype,\n","  File \"/usr/local/lib/python3.10/dist-packages/IPython/core/ultratb.py\", line 1367, in structured_traceback\n","    return FormattedTB.structured_traceback(\n","  File \"/usr/local/lib/python3.10/dist-packages/IPython/core/ultratb.py\", line 1267, in structured_traceback\n","    return VerboseTB.structured_traceback(\n","  File \"/usr/local/lib/python3.10/dist-packages/IPython/core/ultratb.py\", line 1124, in structured_traceback\n","    formatted_exception = self.format_exception_as_a_whole(etype, evalue, etb, number_of_lines_of_context,\n","  File \"/usr/local/lib/python3.10/dist-packages/IPython/core/ultratb.py\", line 1082, in format_exception_as_a_whole\n","    last_unique, recursion_repeat = find_recursion(orig_etype, evalue, records)\n","  File \"/usr/local/lib/python3.10/dist-packages/IPython/core/ultratb.py\", line 382, in find_recursion\n","    return len(records), 0\n","TypeError: object of type 'NoneType' has no len()\n","\n","During handling of the above exception, another exception occurred:\n","\n","Traceback (most recent call last):\n","  File \"/usr/local/lib/python3.10/dist-packages/IPython/core/interactiveshell.py\", line 2099, in showtraceback\n","    stb = value._render_traceback_()\n","AttributeError: 'TypeError' object has no attribute '_render_traceback_'\n","\n","During handling of the above exception, another exception occurred:\n","\n","Traceback (most recent call last):\n","  File \"/usr/local/lib/python3.10/dist-packages/IPython/core/ultratb.py\", line 1101, in get_records\n","    return _fixed_getinnerframes(etb, number_of_lines_of_context, tb_offset)\n","  File \"/usr/local/lib/python3.10/dist-packages/IPython/core/ultratb.py\", line 248, in wrapped\n","    return f(*args, **kwargs)\n","  File \"/usr/local/lib/python3.10/dist-packages/IPython/core/ultratb.py\", line 281, in _fixed_getinnerframes\n","    records = fix_frame_records_filenames(inspect.getinnerframes(etb, context))\n","  File \"/usr/lib/python3.10/inspect.py\", line 1662, in getinnerframes\n","    frameinfo = (tb.tb_frame,) + getframeinfo(tb, context)\n","  File \"/usr/lib/python3.10/inspect.py\", line 1620, in getframeinfo\n","    filename = getsourcefile(frame) or getfile(frame)\n","  File \"/usr/lib/python3.10/inspect.py\", line 829, in getsourcefile\n","    module = getmodule(object, filename)\n","  File \"/usr/lib/python3.10/inspect.py\", line 861, in getmodule\n","    file = getabsfile(object, _filename)\n","  File \"/usr/lib/python3.10/inspect.py\", line 845, in getabsfile\n","    return os.path.normcase(os.path.abspath(_filename))\n","  File \"/usr/lib/python3.10/posixpath.py\", line 384, in abspath\n","    cwd = os.getcwd()\n","OSError: [Errno 107] Transport endpoint is not connected\n"]},{"name":"stderr","output_type":"stream","text":["ERROR:root:Internal Python error in the inspect module.\n","Below is the traceback from this internal error.\n","\n"]},{"name":"stdout","output_type":"stream","text":["Traceback (most recent call last):\n","  File \"/usr/local/lib/python3.10/dist-packages/IPython/core/interactiveshell.py\", line 3553, in run_code\n","    exec(code_obj, self.user_global_ns, self.user_ns)\n","  File \"<ipython-input-73-d6d497bff8bf>\", line 1, in <cell line: 1>\n","    x1 = pickle.load(open('exp34_agrewards.pkl', 'rb'))\n","NameError: name 'pickle' is not defined\n","\n","During handling of the above exception, another exception occurred:\n","\n","Traceback (most recent call last):\n","  File \"/usr/local/lib/python3.10/dist-packages/IPython/core/interactiveshell.py\", line 2099, in showtraceback\n","    stb = value._render_traceback_()\n","AttributeError: 'NameError' object has no attribute '_render_traceback_'\n","\n","During handling of the above exception, another exception occurred:\n","\n","Traceback (most recent call last):\n","  File \"/usr/local/lib/python3.10/dist-packages/IPython/core/interactiveshell.py\", line 3473, in run_ast_nodes\n","    if (await self.run_code(code, result,  async_=asy)):\n","  File \"/usr/local/lib/python3.10/dist-packages/IPython/core/interactiveshell.py\", line 3575, in run_code\n","    self.showtraceback(running_compiled_code=True)\n","  File \"/usr/local/lib/python3.10/dist-packages/IPython/core/interactiveshell.py\", line 2101, in showtraceback\n","    stb = self.InteractiveTB.structured_traceback(etype,\n","  File \"/usr/local/lib/python3.10/dist-packages/IPython/core/ultratb.py\", line 1367, in structured_traceback\n","    return FormattedTB.structured_traceback(\n","  File \"/usr/local/lib/python3.10/dist-packages/IPython/core/ultratb.py\", line 1267, in structured_traceback\n","    return VerboseTB.structured_traceback(\n","  File \"/usr/local/lib/python3.10/dist-packages/IPython/core/ultratb.py\", line 1124, in structured_traceback\n","    formatted_exception = self.format_exception_as_a_whole(etype, evalue, etb, number_of_lines_of_context,\n","  File \"/usr/local/lib/python3.10/dist-packages/IPython/core/ultratb.py\", line 1082, in format_exception_as_a_whole\n","    last_unique, recursion_repeat = find_recursion(orig_etype, evalue, records)\n","  File \"/usr/local/lib/python3.10/dist-packages/IPython/core/ultratb.py\", line 382, in find_recursion\n","    return len(records), 0\n","TypeError: object of type 'NoneType' has no len()\n","\n","During handling of the above exception, another exception occurred:\n","\n","Traceback (most recent call last):\n","  File \"/usr/local/lib/python3.10/dist-packages/IPython/core/interactiveshell.py\", line 2099, in showtraceback\n","    stb = value._render_traceback_()\n","AttributeError: 'TypeError' object has no attribute '_render_traceback_'\n","\n","During handling of the above exception, another exception occurred:\n","\n","Traceback (most recent call last):\n","  File \"/usr/local/lib/python3.10/dist-packages/IPython/core/interactiveshell.py\", line 3030, in _run_cell\n","    return runner(coro)\n","  File \"/usr/local/lib/python3.10/dist-packages/IPython/core/async_helpers.py\", line 78, in _pseudo_sync_runner\n","    coro.send(None)\n","  File \"/usr/local/lib/python3.10/dist-packages/IPython/core/interactiveshell.py\", line 3257, in run_cell_async\n","    has_raised = await self.run_ast_nodes(code_ast.body, cell_name,\n","  File \"/usr/local/lib/python3.10/dist-packages/IPython/core/interactiveshell.py\", line 3492, in run_ast_nodes\n","    self.showtraceback()\n","  File \"/usr/local/lib/python3.10/dist-packages/IPython/core/interactiveshell.py\", line 2101, in showtraceback\n","    stb = self.InteractiveTB.structured_traceback(etype,\n","  File \"/usr/local/lib/python3.10/dist-packages/IPython/core/ultratb.py\", line 1367, in structured_traceback\n","    return FormattedTB.structured_traceback(\n","  File \"/usr/local/lib/python3.10/dist-packages/IPython/core/ultratb.py\", line 1267, in structured_traceback\n","    return VerboseTB.structured_traceback(\n","  File \"/usr/local/lib/python3.10/dist-packages/IPython/core/ultratb.py\", line 1142, in structured_traceback\n","    formatted_exceptions += self.format_exception_as_a_whole(etype, evalue, etb, lines_of_context,\n","  File \"/usr/local/lib/python3.10/dist-packages/IPython/core/ultratb.py\", line 1082, in format_exception_as_a_whole\n","    last_unique, recursion_repeat = find_recursion(orig_etype, evalue, records)\n","  File \"/usr/local/lib/python3.10/dist-packages/IPython/core/ultratb.py\", line 382, in find_recursion\n","    return len(records), 0\n","TypeError: object of type 'NoneType' has no len()\n","\n","During handling of the above exception, another exception occurred:\n","\n","Traceback (most recent call last):\n","  File \"/usr/local/lib/python3.10/dist-packages/IPython/core/interactiveshell.py\", line 2099, in showtraceback\n","    stb = value._render_traceback_()\n","AttributeError: 'TypeError' object has no attribute '_render_traceback_'\n","\n","During handling of the above exception, another exception occurred:\n","\n","Traceback (most recent call last):\n","  File \"/usr/local/lib/python3.10/dist-packages/IPython/core/ultratb.py\", line 1101, in get_records\n","    return _fixed_getinnerframes(etb, number_of_lines_of_context, tb_offset)\n","  File \"/usr/local/lib/python3.10/dist-packages/IPython/core/ultratb.py\", line 248, in wrapped\n","    return f(*args, **kwargs)\n","  File \"/usr/local/lib/python3.10/dist-packages/IPython/core/ultratb.py\", line 281, in _fixed_getinnerframes\n","    records = fix_frame_records_filenames(inspect.getinnerframes(etb, context))\n","  File \"/usr/lib/python3.10/inspect.py\", line 1662, in getinnerframes\n","    frameinfo = (tb.tb_frame,) + getframeinfo(tb, context)\n","  File \"/usr/lib/python3.10/inspect.py\", line 1620, in getframeinfo\n","    filename = getsourcefile(frame) or getfile(frame)\n","  File \"/usr/lib/python3.10/inspect.py\", line 829, in getsourcefile\n","    module = getmodule(object, filename)\n","  File \"/usr/lib/python3.10/inspect.py\", line 861, in getmodule\n","    file = getabsfile(object, _filename)\n","  File \"/usr/lib/python3.10/inspect.py\", line 845, in getabsfile\n","    return os.path.normcase(os.path.abspath(_filename))\n","  File \"/usr/lib/python3.10/posixpath.py\", line 384, in abspath\n","    cwd = os.getcwd()\n","OSError: [Errno 107] Transport endpoint is not connected\n"]}],"source":["x1 = pickle.load(open('exp34_agrewards.pkl', 'rb'))\n","x2 = pickle.load(open('exp35_agrewards.pkl', 'rb'))\n","x3 = pickle.load(open('exp36_agrewards.pkl', 'rb'))\n","\n","plot_rewards_subplots('simple_speaker_listener', 0, 2, x1, x2, x3)"]},{"cell_type":"code","execution_count":null,"metadata":{"id":"RSPS7L8aMfaw"},"outputs":[],"source":["def plot_reward_differences(env_name, m, n, rewards_ddpg, rewards_adv_ddpg_good_kl, rewards_adv_kl_good_ddpg, save_path):\n","    plt.figure(figsize=(20,10))\n","\n","    # Compute differences\n","    diff_adv = np.array(rewards_adv_kl_good_ddpg) - np.array(rewards_adv_ddpg_good_kl)\n","    diff_good = np.array(rewards_adv_kl_good_ddpg) - np.array(rewards_ddpg)\n","\n","    for i in range(m+n):\n","        if i < m:\n","            label = 'Adv Agent'\n","        else:\n","            label = 'Good Agent'\n","\n","        plt.subplot(2, 1, 1)\n","        plt.plot(diff_adv[i*10:(i+1)*10], label=f'{label} {i+1}')\n","        plt.title(f\"[{env_name}]: Difference in rewards for Adv Agents (KL-DDPG)\")\n","        plt.xlabel(\"Iteration Number\")\n","        plt.ylabel(\"Difference in Reward\")\n","        plt.legend()\n","\n","        plt.subplot(2, 1, 2)\n","        plt.plot(diff_good[i*10:(i+1)*10], label=f'{label} {i+1}')\n","        plt.title(f\"[{env_name}]: Difference in rewards for Good Agents (KL-DDPG)\")\n","        plt.xlabel(\"Iteration Number\")\n","        plt.ylabel(\"Difference in Reward\")\n","        plt.legend()\n","\n","    plt.tight_layout()  # Ensure subplots do not overlap\n","    plt.savefig(save_path)  # Save the plot to your Google Drive\n","    plt.show()  # Display the plot\n"]},{"cell_type":"code","execution_count":null,"metadata":{"id":"ku8lca1Gbd2h"},"outputs":[],"source":[]}],"metadata":{"colab":{"authorship_tag":"ABX9TyMeancIH7mG/1kfActaus1u","provenance":[]},"kernelspec":{"display_name":"Python 3","name":"python3"},"language_info":{"name":"python"}},"nbformat":4,"nbformat_minor":0}
